<robot xmlns:xacro="http://www.ros.org/wiki/xacro">

    <xacro:include filename="$(find rm_description)/urdf/sentry/driven_wheel.urdf.xacro"/>

    <xacro:macro name="chassis" params="use_simulation">

        <link name="base_link">
            <inertial>
                <mass value="6982.046e-3"/>
                <origin xyz="2.335e-3 21.529e-3 -63.905e-3"/>
                <inertia ixx="1.984e-1" ixy="1.366e-3" ixz="2.748e-3" iyy="1.284e-1"
                         iyz="3.820e-3" izz="1.524e-1"/>
            </inertial>
            <visual>
                <origin xyz="0 0 0" rpy="0 0 0"/>
                <geometry>
                    <mesh filename="package://rm_description/meshes/sentry/base_link.stl" scale="0.001 0.001 0.001"/>
                </geometry>
            </visual>
            <collision>
                <origin xyz="0 0 0" rpy="0 0 0"/>
                <geometry>
                    <mesh filename="package://rm_description/meshes/sentry/base_link.stl" scale="0.001 0.001 0.001"/>
                </geometry>
            </collision>
        </link>

        <link name="drive_wheel_link">
            <inertial>
                <mass value="65.448e-3"/>
                <origin xyz="0.027e-3 29.066e-3 0.001e-3"/>
                <inertia ixx="74809.989e-9" ixy="-10.328e-9" ixz="-0.001e-9" iyy="32620.511e-9"
                         iyz="-2.066e-9" izz="74795.135e-9"/>
            </inertial>
            <visual>
                <origin xyz="0 0 0" rpy="0 0 0"/>
                <geometry>
                    <mesh filename="package://rm_description/meshes/sentry/drive_wheel.stl" scale="0.001 0.001 0.001"/>
                </geometry>
            </visual>
            <collision>
                <origin xyz="0 0 0" rpy="0 0 0"/>
                <geometry>
                    <mesh filename="package://rm_description/meshes/sentry/drive_wheel.stl" scale="0.001 0.001 0.001"/>
                </geometry>
            </collision>
        </link>

        <joint name="drive_wheel_joint" type="revolute">
            <axis xyz="0 1 0"/>
            <limit effort="1.2" velocity="34" lower="-1e9" upper="1e9"/>
            <parent link="base_link"/>
            <child link="drive_wheel_link"/>
            <origin xyz="0 -63.36e-3 5e-3" rpy="0 0 0"/>
        </joint>

        <xacro:if value="$(arg use_simulation)">
            <xacro:driven_wheel num="1">
                <origin rpy="${-pi/2} 0 0"/>
                <axis xyz="0 1 0"/>
                <origin xyz="-0.0977 0.0839 -0.013" rpy="0 0 0"/>
            </xacro:driven_wheel>

            <xacro:driven_wheel num="2">
                <origin rpy="${-pi/2} 0 0"/>
                <axis xyz="0 1 0"/>
                <origin xyz="0.0977 0.0839 -0.013" rpy="0 0 0"/>
            </xacro:driven_wheel>

            <xacro:driven_wheel num="3">
                <origin rpy="0 0 0"/>
                <axis xyz="0 0 1"/>
                <origin xyz="-0.0982 0.135 -0.0571" rpy="0 0 0"/>
            </xacro:driven_wheel>

            <xacro:driven_wheel num="4">
                <origin rpy="0 0 0"/>
                <axis xyz="0 0 1"/>
                <origin xyz="0.0982 0.135 -0.0571" rpy="0 0 0"/>
            </xacro:driven_wheel>

            <xacro:driven_wheel num="5">
                <origin rpy="0 0 0"/>
                <axis xyz="0 0 1"/>
                <origin xyz="0 -0.073 -0.0572" rpy="0 0 0"/>
            </xacro:driven_wheel>
        </xacro:if>

    </xacro:macro>

    <!--    <link name="cover">-->
    <!--    <inertial>-->
    <!--        <mass value="0.118"/>-->
    <!--        <origin xyz="-0.037 -0.003 0.0"/>-->
    <!--        <inertia ixx="6.240e-4" ixy="7.325e-4" ixz="1.839e-5" iyy="1.083e-3" iyz="-1.166e-5" izz="1.602e-3"/>-->
    <!--    </inertial>-->
    <!--    </link>-->

    <!--    <joint name="cover_joint" type="revolute">-->
    <!--        <axis xyz="1 0 0"/>-->
    <!--        <origin xyz="-0.27 0.201 0.125"/>-->
    <!--        <limit effort="1" velocity="30" lower="-3.14" upper="3.14"/>-->
    <!--        <dynamics damping="0.0" friction="0.1"/>-->
    <!--        <parent link="pitch"/>-->
    <!--        <child link="cover"/>-->
    <!--    </joint>-->

    <!--    <transmission name="trans_cover_joint">-->
    <!--        <type>transmission_interface/SimpleTransmission</type>-->
    <!--        <actuator name="cover_joint_motor">-->
    <!--            <mechanicalReduction>1</mechanicalReduction>-->
    <!--        </actuator>-->
    <!--        <joint name="cover_joint">-->
    <!--            <offset>0</offset>-->
    <!--            <hardwareInterface>hardware_interface/EffortJointInterface</hardwareInterface>-->
    <!--        </joint>-->
    <!--    </transmission>-->

</robot>