<robot xmlns:xacro="http://www.ros.org/wiki/xacro">

  <xacro:property name="wheel_joint_effort" value="5"/>
  <xacro:property name="wheel_joint_velocity" value="50"/>

  <xacro:macro name="driven_wheel" params="num *pose *axis *origin">
    <link name="link_driven_wheel${num}">
      <visual>
        <xacro:insert_block name="pose"/>
        <geometry>
          <mesh filename="package://rm_description/meshes/sentry/driven_wheel.stl"
                scale="0.001 0.001 0.001"/>
        </geometry>
      </visual>
      <inertial>
        <mass value="9.665e-3"/>
        <origin xyz="0 0 0" rpy="0 0 0"/>
        <inertia ixx="7.0766e-7" ixy="0" ixz="0" iyy="1.0067e-6"
                 iyz="0" izz="7.0766e-7"/>
      </inertial>
      <collision>
        <origin xyz="0 0 0" rpy="0 0 0"/>
        <geometry>
          <mesh filename="package://rm_description/meshes/sentry/driven_wheel.stl"
                scale="0.001 0.001 0.001"/>
        </geometry>
      </collision>
    </link>

    <joint name="joint_wheel${num}" type="continuous">
      <parent link="base_link"/>
      <child link="link_driven_wheel${num}"/>
      <xacro:insert_block name="axis"/>
      <xacro:insert_block name="origin"/>
      <limit effort="${wheel_joint_effort}" velocity="${wheel_joint_velocity}" lower="-1e16" upper="1e16"/>
      <dynamics damping="0.0" friction="0.05"/>
    </joint>

  </xacro:macro>

</robot>