<?xml version="1.0" encoding="utf-8"?>
<robot xmlns:xacro="http://www.ros.org/wiki/xacro">

    <xacro:property name="threshold" value="0.1"/>
    <xacro:property name="pitch_lower_limit" value="-0.7"/>
    <xacro:property name="pitch_upper_limit" value="0.45"/>

        <link name="yaw">
            <inertial>
                <mass value="1.337"/>
                <origin xyz="0.00072 0.000098 0.00976"/>
                <inertia ixx="4.777e-3" ixy="-1.108e-5" ixz="1.574e-5" iyy="4.902e-3"
                         iyz="-1.234e-5" izz="3.643e-3"/>
            </inertial>
            <visual>
                <origin xyz="0 0 0" rpy="0 0 0"/>
                <geometry>
                    <mesh filename="package://rm_description/meshes/standard/yaw.stl" scale="0.001 0.001 0.001"/>
                </geometry>
            </visual>
            <collision>
                <origin xyz="0 0 0" rpy="0 0 0"/>
                <geometry>
                    <mesh filename="package://rm_description/meshes/standard/yaw.stl" scale="0.001 0.001 0.001"/>
                </geometry>
            </collision>
        </link>

        <joint name="yaw_joint" type="revolute">
            <origin xyz="0 0 0.0696"
                    rpy="0 0 0"/>
            <dynamics damping="0.0" friction="0.1"/>
            <limit effort="1.2" velocity="31" lower="-1e10" upper="1e10"/>
            <parent link="base_link"/>
            <child link="yaw"/>
            <axis xyz="0 0 1"/>
        </joint>

        <link name="pitch">
            <inertial>
                <mass value="1.175"/>
                <origin xyz="-0.00439 0.0113 -0.00970"/>
                <inertia ixx="4.716e-3" ixy="-1.511e-4" ixz="-1.134e-4" iyy="5.220e-3"
                         iyz="1.192e-5" izz="6.046e-3"/>
            </inertial>
            <visual>
                <origin xyz="0 0 0" rpy="0 0 0"/>
                <geometry>
                    <mesh filename="package://rm_description/meshes/standard/pitch.stl" scale="0.001 0.001 0.001"/>
                </geometry>
            </visual>
            <collision>
                <origin xyz="0 0 0" rpy="0 0 0"/>
                <geometry>
                    <mesh filename="package://rm_description/meshes/standard/pitch.stl" scale="0.001 0.001 0.001"/>
                </geometry>
            </collision>
        </link>

        <joint name="pitch_joint" type="revolute">
            <origin xyz="0 0 0.189" rpy="0 0 0"/>
            <dynamics damping="0.0" friction="0.1"/>
            <limit effort="1.2" velocity="13.82" lower="${pitch_lower_limit}" upper="${pitch_upper_limit}"/>
            <safety_controller k_position="100" k_velocity="0.1"
                               soft_lower_limit="${pitch_lower_limit+threshold}"
                               soft_upper_limit="${pitch_upper_limit-threshold}"/>
            <parent link="yaw"/>
            <child link="pitch"/>
            <axis xyz="0 1 0 "/>
        </joint>

</robot>
