<?xml version="1.0" encoding="utf-8"?>
<robot xmlns:xacro="http://www.ros.org/wiki/xacro">

    <xacro:property name="threshold" value="0.1"/>
    <xacro:property name="pitch_lower_limit" value="-0.7"/>
    <xacro:property name="pitch_upper_limit" value="0.45"/>

        <link name="yaw">
            <inertial>
                <mass value="0.592087"/>
                <origin xyz="0 0 0.0127"/>
                <inertia ixx="6.17e-4" ixy="0." ixz="0." iyy="6.182e-4"
                         iyz="0." izz="1.07e-3"/>
            </inertial>
            <visual>
                <origin xyz="0 0 0" rpy="0 0 0"/>
                <geometry>
                    <mesh filename="package://rm_description/meshes/standard/yaw.stl" scale="0.001 0.001 0.001"/>
                </geometry>
            </visual>
            <collision>
                <origin xyz="0 0 0" rpy="0 0 0"/>
                <geometry>
                    <mesh filename="package://rm_description/meshes/standard/yaw.stl" scale="0.001 0.001 0.001"/>
                </geometry>
            </collision>
        </link>

        <joint name="yaw_joint" type="revolute">
            <origin xyz="0 0 0.0696"
                    rpy="0 0 0"/>
            <dynamics damping="0.0" friction="0.1"/>
            <limit effort="1.2" velocity="31" lower="-1e10" upper="1e10"/>
            <parent link="base_link"/>
            <child link="yaw"/>
            <axis xyz="0 0 1"/>
        </joint>

        <link name="pitch">
            <inertial>
                <mass value="1.475"/>
                <origin xyz="0.0168 -0.0028 0.0225"/>
                <inertia ixx="5.619e-3" ixy="1.192e-4" ixz="-1.795e-4" iyy="6.577e-3"
                         iyz="8.931e-5" izz="6.867e-3"/>
            </inertial>
            <visual>
                <origin xyz="0 0 0" rpy="0 0 0"/>
                <geometry>
                    <mesh filename="package://rm_description/meshes/standard/pitch.stl" scale="0.001 0.001 0.001"/>
                </geometry>
            </visual>
            <collision>
                <origin xyz="0 0 0" rpy="0 0 0"/>
                <geometry>
                    <mesh filename="package://rm_description/meshes/standard/pitch.stl" scale="0.001 0.001 0.001"/>
                </geometry>
            </collision>
        </link>

        <joint name="pitch_joint" type="revolute">
            <origin xyz="0 0 0.189" rpy="0 0 0"/>
            <dynamics damping="0.0" friction="0.1"/>
            <limit effort="1.2" velocity="13.82" lower="${pitch_lower_limit}" upper="${pitch_upper_limit}"/>
            <safety_controller k_position="100" k_velocity="0.1"
                               soft_lower_limit="${pitch_lower_limit+threshold}"
                               soft_upper_limit="${pitch_upper_limit-threshold}"/>
            <parent link="yaw"/>
            <child link="pitch"/>
            <axis xyz="0 1 0 "/>
        </joint>

</robot>
