<robot xmlns:xacro="http://www.ros.org/wiki/xacro">

    <xacro:include filename="$(find rm_description)/urdf/common/friction.urdf.xacro"/>
<!--    <xacro:include filename="$(find rm_description)/urdf/standard/gimbal.urdf.xacro"/>-->


    <xacro:property name="wheel_offset_x" value="0.00884"/>
    <xacro:property name="wheel_offset_y" value="0.036564"/>
    <xacro:property name="wheel_offset_z" value="0.0"/>


    <xacro:friction_wheel prefixs="left" connected_to="pitch"
                          wheel_x_offset="${wheel_offset_x}" wheel_y_offset="${wheel_offset_y}"
                          wheel_z_offset="${wheel_offset_z}"/>

    <xacro:friction_wheel prefixs="right" connected_to="pitch"
                          wheel_x_offset="${wheel_offset_x}" wheel_y_offset="${-wheel_offset_y}"
                          wheel_z_offset="${wheel_offset_z}"/>


    <link name="trigger">
        <inertial>
            <mass value="0.2972"/>
            <origin xyz="-0.00549 -0.00233 0.00344"/>
            <inertia ixx="1.955e-4" ixy="-2.402e-5" ixz="-2.718e-5" iyy="3.514e-4"
                     iyz="-6.239e-6" izz="4.209e-4"/>
        </inertial>
        <visual>
            <origin xyz="0 0 0" rpy="0 0 0"/>
            <geometry>
                <mesh filename="package://rm_description/meshes/standard/trigger.stl" scale="0.001 0.001 0.001"/>
            </geometry>
        </visual>
        <collision>
            <origin xyz="0 0 0" rpy="0 0 0"/>
            <geometry>
                <mesh filename="package://rm_description/meshes/standard/trigger.stl" scale="0.001 0.001 0.001"/>
            </geometry>
        </collision>
    </link>

    <joint name="trigger_joint" type="continuous">
        <origin xyz="-0.064 0 0" rpy="0 0 0"/>
        <dynamics damping="0.0" friction="0.01"/>
        <limit effort="1.0" velocity="43.54" lower="-1e16" upper="1e16"/>
        <parent link="pitch"/>
        <child link="trigger"/>
        <axis xyz="0 0 1 "/>

    </joint>

    <link name="cover">
        <inertial>
            <mass value="0.149"/>
            <origin xyz="-0.008 -0.005 0.019"/>
            <inertia ixx="2.366e-3" ixy="-2.372e-4" ixz="-7.983e-4" iyy="2.959e-3" iyz="-2.826e-4" izz="9.090e-4"/>
        </inertial>
        <visual>
            <origin xyz="0 0 0" rpy="0 0 0"/>
            <geometry>
                <mesh filename="package://rm_description/meshes/standard/cover.stl" scale="0.001 0.001 0.001"/>
            </geometry>
        </visual>
        <collision>
            <origin xyz="0.033 0.0 -0.0" rpy="0 0.0 0"/>
            <geometry>
                <mesh filename="package://rm_description/meshes/standard/cover.stl" scale="0.001 0.001 0.001"/>
            </geometry>
        </collision>
    </link>

    <joint name="cover_joint" type="revolute">
        <axis xyz="0 0 1"/>
        <origin xyz="0.037 0.042 0.122"/>
        <limit effort="1.0" velocity="30" lower="-3.14" upper="3.14"/>
        <dynamics damping="0.0" friction="0.1"/>
        <parent link="pitch"/>
        <child link="cover"/>
    </joint>

</robot>
