<robot xmlns:xacro="http://www.ros.org/wiki/xacro">

    <xacro:macro name="swerve_drive"
                 params="prefix wheel_x_offset wheel_y_offset wheel_z_offset  connected_to reflect mirror">

        <link name="${prefix}_pivot">
            <visual>
                <origin xyz="0 0 0" rpy="0 0 0"/>
                <geometry>
                    <xacro:if value="${reflect == 1}">
                        <mesh filename="package://rm_description/meshes/common/right_front_swerve_pivot.stl"
                              scale="0.001 0.001 0.001"/>
                    </xacro:if>
                    <xacro:if value="${reflect == -1}">
                        <mesh filename="package://rm_description/meshes/common/left_front_swerve_pivot.stl"
                              scale="0.001 0.001 0.001"/>
                    </xacro:if>
                </geometry>
            </visual>
            <inertial>
                <xacro:if value="${reflect == 1}">
                    <mass value="0.854"/>
                    <origin xyz="0.000054 0.008 0.00548" rpy="0 0 0"/>
                    <inertia ixx="6.711e-4" ixy="1.958e-9" ixz="-1.109e-6" iyy="6.703e-4" iyz="-1.095e-7"
                             izz="7.091e-4"/>
                </xacro:if>
                <xacro:if value="${reflect == -1}">
                    <mass value="0.854"/>
                    <origin xyz="0.000054 0.008 0.00548" rpy="0 0 0"/>
                    <inertia ixx="6.711e-4" ixy="1.958e-9" ixz="-1.109e-6" iyy="6.703e-4" iyz="-1.095e-7"
                             izz="7.091e-4"/>
                </xacro:if>
            </inertial>
            <collision>
                <origin xyz="0 0 0" rpy="0 0 0"/>
                <geometry>
                    <xacro:if value="${reflect == 1}">
                        <mesh filename="package://rm_description/meshes/common/right_front_swerve_pivot.stl"
                              scale="0.001 0.001 0.001"/>
                    </xacro:if>
                    <xacro:if value="${reflect == -1}">
                        <mesh filename="package://rm_description/meshes/common/left_front_swerve_pivot.stl"
                              scale="0.001 0.001 0.001"/>
                    </xacro:if>
                </geometry>
            </collision>
        </link>

        <joint name="${prefix}_pivot_joint" type="continuous">
            <axis xyz="0 0 1"/>
            <xacro:if value="${mirror == 1}">
                <origin xyz="${wheel_x_offset} ${wheel_y_offset} ${wheel_z_offset}" rpy="0 0 0"/>
            </xacro:if>
            <xacro:if value="${mirror == -1}">
                <origin xyz="${wheel_x_offset} ${wheel_y_offset} ${wheel_z_offset}" rpy="0 0 ${pi}"/>
            </xacro:if>
            <parent link="${connected_to}"/>
            <child link="${prefix}_pivot"/>
            <dynamics damping="0.0" friction="0.1"/>
            <limit effort="1.2" velocity="31" lower="-1e10" upper="1e10"/>
        </joint>


        <link name="${prefix}_wheel">
            <visual>
                <origin xyz="0 0.0265 0" rpy="0 0 0"/>
                <geometry>
                    <mesh filename="package://rm_description/meshes/common/swerve_wheel.stl"
                          scale="0.001 0.001 0.001"/>
                </geometry>
            </visual>
            <inertial>
                <mass value="0.543"/>
                <origin xyz="0.000024 0.024 0.000129" rpy="0 0 0"/>
                <inertia ixx="4.895e-4" ixy="-3.948e-7" ixz="1.726e-7" iyy="2.894e-4" iyz="1.133e-6" izz="4.887e-4"/>
            </inertial>
            <collision>
                <origin xyz="0 0 0" rpy="${pi/2.} 0 0"/>
                <geometry>
                    <cylinder radius="0.05" length="0.053"/>
                </geometry>
            </collision>
        </link>

        <joint name="${prefix}_wheel_joint" type="continuous">
            <axis xyz="0 1 0"/>
            <origin xyz="0 0 -0.112" rpy="0 0 0"/>
            <parent link="${prefix}_pivot"/>
            <child link="${prefix}_wheel"/>
            <limit effort="2.2" velocity="68" lower="-1e10" upper="1e10"/>
            <dynamics damping="0.0" friction="0.05"/>
        </joint>

        <gazebo reference="${prefix}_wheel">
            <mu1 value="20"/>
            <mu2 value="20"/>
            <kp value="1000000.0"/>
            <kd value="100.0"/>
            <material>Gazebo/Black</material>
        </gazebo>
    </xacro:macro>

    <xacro:macro name="swerve_transmission" params="prefix wheel_reduction  pivot_offset">

        <transmission name="${prefix}_pivot_trans">
            <type>transmission_interface/SimpleTransmission</type>
            <actuator name="${prefix}_pivot_motor">
                <mechanicalReduction>-1</mechanicalReduction>
            </actuator>
            <joint name="${prefix}_pivot_joint">
                <offset>${pivot_offset}</offset>
                <hardwareInterface>hardware_interface/EffortJointInterface</hardwareInterface>
            </joint>
        </transmission>

        <transmission name="${prefix}_wheel_trans">
            <type>transmission_interface/SimpleTransmission</type>
            <actuator name="${prefix}_wheel_motor">
                <mechanicalReduction>${wheel_reduction}</mechanicalReduction>
            </actuator>
            <joint name="${prefix}_wheel_joint">
                <hardwareInterface>hardware_interface/EffortJointInterface</hardwareInterface>
            </joint>
        </transmission>
    </xacro:macro>

</robot>
