<?xml version="1.0" encoding="utf-8"?>
<robot xmlns:xacro="http://www.ros.org/wiki/xacro" name="arm">

    <xacro:macro name="arm" params="connected_to">

        <!--  link  -->
        <link name="link1">
            <inertial>
                <mass value="1.768"/>
                <origin xyz="-0.005 0.046 0.0"/>
                <inertia ixx="9.816e-3" ixy="-2.523e-4" ixz="7.839e-6" iyy="9.203e-3" iyz="9.389e-5" izz="3.735e-3"/>
            </inertial>
            <visual>
                <origin xyz="0 0 0" rpy="0 0 0"/>
                <geometry>
                    <mesh filename="package://rm_description/meshes/engineer/link1.stl" scale="0.001 0.001 0.001"/>
                </geometry>
            </visual>
            <collision>
                <origin xyz="-0.045 0 0.035" rpy="0 0 0"/>
                <geometry>
                    <box size="0.15 0.106 0.07"/>
                </geometry>
            </collision>
            <collision>
                <origin xyz="0.040 0 0.1" rpy="0 -0.95993 0"/>
                <geometry>
                    <box size="0.17 0.106 0.095"/>
                </geometry>
            </collision>
            <collision>
                <origin xyz="0 0 0.05" rpy="1.5707963 0 0"/>
                <geometry>
                    <cylinder length="0.188" radius="0.047"/>
                </geometry>
            </collision>
        </link>

        <link name="link2">
            <inertial>
                <mass value="1.256"/>
                <origin xyz="0.057 0.002 0"/>
                <inertia ixx="1.678e-3" ixy="1.267e-5" ixz="-4.26e-7" iyy="3.761e-3" iyz="1.345e-6" izz="4.111e-3"/>
            </inertial>
            <visual>
                <origin xyz="0 0 0" rpy="0 0 0"/>
                <geometry>
                    <mesh filename="package://rm_description/meshes/engineer/link2.stl" scale="0.001 0.001 0.001"/>
                </geometry>
            </visual>
            <collision>
                <origin xyz="0.062 0 0"/>
                <geometry>
                    <box size="0.225 0.096 0.070"/>
                </geometry>
            </collision>
        </link>

        <link name="link3">
            <inertial>
                <mass value="1.139"/>
                <origin xyz="0.081 -0.0 0.022"/>
                <inertia ixx="9.633e-4" ixy="-2.836e-4" ixz="-5.244e-4" iyy="2.739e-3" iyz="-8.552e-5" izz="2.963e-3"/>
            </inertial>
            <visual>
                <origin xyz="0 0 0" rpy="0 0 0"/>
                <geometry>
                    <mesh filename="package://rm_description/meshes/engineer/link3.stl" scale="0.001 0.001 0.001"/>
                </geometry>
            </visual>
            <collision>
                <origin xyz="0.063 0 0"/>
                <geometry>
                    <box size="0.191 0.084 0.053"/>
                </geometry>
            </collision>
            <collision>
                <origin xyz="0 0 0" rpy="1.5707963 0 0"/>
                <geometry>
                    <cylinder length="0.082" radius="0.047"/>
                </geometry>
            </collision>
        </link>

        <link name="link4">
            <inertial>
                <mass value="0.362"/>
                <origin xyz="0.035 -0.027 0.06"/>
                <inertia ixx="8.647e-4" ixy="-5.427e-5" ixz="-1.425e-4" iyy="8.477e-4" iyz="-2.555e-4" izz="5.668e-4"/>
            </inertial>
            <visual>
                <origin xyz="0 0 0" rpy="0 0 0"/>
                <geometry>
                    <mesh filename="package://rm_description/meshes/engineer/link4.stl" scale="0.001 0.001 0.001"/>
                </geometry>
            </visual>
            <collision>
                <origin xyz="0 0 0" rpy="0 0 0"/>
                <geometry>
                    <box size="0.0513 0.074 0.0513"/>
                </geometry>
            </collision>
        </link>

        <link name="link5">
            <inertial>
                <mass value="0.85"/>
                <origin xyz="-0.061 0.0 0.0"/>
                <inertia ixx="1.761e-4" ixy="6.99e-7" ixz="1.26e-7" iyy="5.874e-4" iyz="2.72e-7" izz="5.863e-4"/>
            </inertial>
            <visual>
                <origin xyz="0 0 0" rpy="0 0 0"/>
                <geometry>
                    <mesh filename="package://rm_description/meshes/engineer/link5.stl" scale="0.001 0.001 0.001"/>
                </geometry>
            </visual>
            <collision>
                <origin xyz="0.015 0 0" rpy="0 0 0"/>
                <geometry>
                    <box size="0.056 0.0513 0.0513"/>
                </geometry>
            </collision>
        </link>

        <!--  joint  -->
        <joint name="joint1" type="revolute">
            <axis xyz="0 0 1"/>
            <origin xyz="0.133 0 1" rpy="1.57 0 0"/>
            <!--      limit not work while type="continuous"-->
            <limit effort="20" velocity="25" lower="-${pi}" upper="${pi}"/>
            <dynamics damping="0.0" friction="0.1"/>
            <parent link="${connected_to}"/>
            <child link="link1"/>
        </joint>

        <joint name="joint2" type="revolute">
            <axis xyz="0 1 0"/>
            <origin xyz="0.005 0.128 0" rpy="-1.57 0 0"/>
            <limit effort="30" velocity="10" lower="-2.231" upper="0.407"/>
            <dynamics damping="0.0" friction="0.8"/>
            <parent link="link1"/>
            <child link="link2"/>
        </joint>

        <joint name="joint3" type="revolute">
            <axis xyz="0 1 0"/>
            <origin xyz="0.165 0 0" rpy="0 0 0"/>
            <limit effort="30" velocity="10" lower="-2.1645" upper="2.4078"/>
            <dynamics damping="0.0" friction="0.5"/>
            <parent link="link2"/>
            <child link="link3"/>
        </joint>

        <joint name="joint4" type="revolute">
            <axis xyz="0 1 0"/>
            <origin xyz="0.106 0 0.028"/>
            <limit effort="2.4" velocity="34" lower="-${0.55*pi}" upper="${0.55*pi}"/>
            <dynamics damping="0.0" friction="0.05"/>
            <parent link="link3"/>
            <child link="link4"/>
        </joint>

        <joint name="joint5" type="revolute">
            <axis xyz="1 0 0"/>
            <origin xyz="0.097 0 0.055"/>
            <limit effort="1.2" velocity="34" lower="-${pi}" upper="${pi}"/>
            <dynamics damping="0.0" friction="0.05"/>
            <parent link="link4"/>
            <child link="link5"/>
        </joint>

    </xacro:macro>
</robot>