<robot xmlns:xacro="http://www.ros.org/wiki/xacro" name="chassis">

    <xacro:include filename="$(find rm_description)/urdf/common/mecanum_wheel.urdf.xacro"/>

    <!-- https://upload.wikimedia.org/wikipedia/commons/5/52/Wheelbase_and_Track.png -->
    <xacro:property name="wheel_front" value="0.091"/>
    <xacro:property name="wheel_back" value="-0.178"/>
    <xacro:property name="wheel_left" value="-0.245"/>
    <xacro:property name="wheel_right" value="0.245"/>
    <xacro:property name="wheel_offset_z" value="-0.04"/>
    <xacro:property name="wheel_joint_damping" value="1.0"/>
    <xacro:property name="wheel_joint_friction" value="1.0"/>

    <xacro:macro name="chassis" params="roller_type">

        <link name="base_link">
            <inertial>
                <mass value="11.91"/>
                <origin xyz="-0.063 -0.010 -0.027"/>
                <inertia ixx="4.230e-1" ixy="-5.057e-4" ixz="3.328e-2" iyy="3.602e-1"
                         iyz="1.417e-2" izz="5.140e-1"/>
            </inertial>
            <visual>
                <origin xyz="0 0 0" rpy="0 0 0"/>
                <geometry>
                    <mesh filename="package://rm_description/meshes/engineer/base.stl" scale="0.001 .001 0.001"/>
                </geometry>
            </visual>
            <collision>
                <origin xyz="-0.043 0 0.020" rpy="0 0 0"/>
                <geometry>
                    <box size="0.486 0.596 0.169"/>
                </geometry>
            </collision>
                        <collision>
                            <origin xyz="-0.130 -0.132 0.255" rpy="0 0 0.8377580"/>
                            <geometry>
                                <box size="0.106 0.186 0.3"/>
                            </geometry>
                        </collision>
                        <collision>
                            <origin xyz="-0.0336 -0.27 0.262" rpy="0 0 -0.7853982"/>
                            <geometry>
                                <box size="0.01 0.033 0.06"/>
                            </geometry>
                        </collision>
            <collision>
                <origin xyz="-0.083 -0.225 0.262" rpy="0 0 -0.7853982"/>
                <geometry>
                    <box size="0.01 0.033 0.06"/>
                </geometry>
            </collision>
            <collision>
                <origin xyz="-0.0685 -0.259 0.287" rpy="0 0 0.8377580"/>
                <geometry>
                    <box size="0.003 0.057 0.01"/>
                </geometry>
            </collision>
            <collision>
                <origin xyz="-0.0685 -0.259 0.237" rpy="0 0 0.8377580"/>
                <geometry>
                    <box size="0.003 0.057 0.01"/>
                </geometry>
            </collision>

            <collision>
                <origin xyz="-0.08 0.243 0.258" rpy="0 0 -0.5061455"/>
                <geometry>
                    <box size="0.08 0.0217 0.3033"/>
                </geometry>
            </collision>
            <collision>
                <origin xyz="-0.21 0.19 0.25833" rpy="0 0 1.0646508"/>
                <geometry>
                    <box size="0.08 0.0217 0.3033"/>
                </geometry>
            </collision>
            <collision>
                <origin xyz="-0.19 0.05 0.258" rpy="0 0 -0.5061455"/>
                <geometry>
                    <box size="0.08 0.0217 0.3033"/>
                </geometry>
            </collision>
            <collision>
                <origin xyz="0.0 0 0" rpy="0 0 1.0646508"/>
                <geometry>
                    <box size="0.080 0.003 0.250"/>
                </geometry>
            </collision>
        </link>

        <link name="stone_platform">
            <inertial>
                <mass value="0.073"/>
                <origin xyz="-0.037 -0.005 0.009"/>
                <inertia ixx="5.874e-4" ixy="-2.845e-4" ixz="1.882e-5" iyy=" 2.133e-4" iyz="2.682e-5" izz="7.780e-4"/>
            </inertial>
            <visual>
                <origin xyz="0 0 0" rpy="0 0 0"/>
                <geometry>
                    <mesh filename="package://rm_description/meshes/engineer/stone_platform.stl" scale="0.001 0.001 0.001"/>
                </geometry>
            </visual>
            <collision>
                <origin xyz="-0.113 0.134 0.114" rpy="0 0.0 0"/>
                <geometry>
                    <box size="0.106 0.105 0.002"/>
                </geometry>
            </collision>
        </link>

        <joint name="stone_platform_joint" type="prismatic">
            <axis xyz="0 0 1"/>
            <origin xyz="-0.113 0.134 0.114"/>
            <limit effort="7" velocity="30" lower="0" upper="2.6459"/>
            <dynamics damping="0.0" friction="0.1"/>
            <parent link="base_link"/>
            <child link="stone_platform"/>
        </joint>

        <transmission name="trans_stone_platform_joint">
            <type>transmission_interface/SimpleTransmission</type>
            <actuator name="stone_platform_joint_motor">
                <mechanicalReduction>49.97</mechanicalReduction>
            </actuator>
            <joint name="stone_platform_joint">
                <hardwareInterface>hardware_interface/EffortJointInterface</hardwareInterface>
                <offset>0</offset>
            </joint>
        </transmission>


        <xacro:mecanum_wheel prefix="left_front" connected_to="base_link"
                             wheel_x_offset="${wheel_front}" wheel_y_offset="${wheel_left}"
                             wheel_z_offset="${wheel_offset_z}"
                             reflect="1" roller_type="${roller_type}"/>
        <xacro:mecanum_wheel prefix="right_front" connected_to="base_link"
                             wheel_x_offset="${wheel_front}" wheel_y_offset="${wheel_right}"
                             wheel_z_offset="${wheel_offset_z}"
                             reflect="-1" roller_type="${roller_type}"/>
        <xacro:mecanum_wheel prefix="left_back" connected_to="base_link"
                             wheel_x_offset="${wheel_back}" wheel_y_offset="${wheel_left}"
                             wheel_z_offset="${wheel_offset_z}"
                             reflect="-1" roller_type="${roller_type}"/>
        <xacro:mecanum_wheel prefix="right_back" connected_to="base_link"
                             wheel_x_offset="${wheel_back}" wheel_y_offset="${wheel_right}"
                             wheel_z_offset="${wheel_offset_z}"
                             reflect="1" roller_type="${roller_type}"/>
        <xacro:wheel_transmission prefix="left_front" mechanical_reduction="19.2032"/>
        <xacro:wheel_transmission prefix="right_front" mechanical_reduction="-19.2032"/>
        <xacro:wheel_transmission prefix="left_back" mechanical_reduction="19.2032"/>
        <xacro:wheel_transmission prefix="right_back" mechanical_reduction="-19.2032"/>

    </xacro:macro>

</robot>