<?xml version="1.0" ?>
<!-- =================================================================================== -->
<!-- |    This document was autogenerated by xacro from engineer.urdf.xacro            | -->
<!-- |    EDITING THIS FILE BY HAND IS NOT RECOMMENDED                                 | -->
<!-- =================================================================================== -->
<robot name="engineer">
  <link name="base_link">
    <inertial>
      <mass value="28.19"/>
      <origin xyz="-0.0206 -0.00126 -0.0164"/>
      <inertia ixx="1.32e+0" ixy="-8.378e-2" ixz="6.28e-2" iyy="1.549e+0" iyz="5.948e-2" izz="2.024e+0"/>
    </inertial>
    <visual>
      <origin rpy="0 0 0" xyz="0 0 0"/>
      <geometry>
        <mesh filename="package://rm_description/meshes/engineer/base.stl" scale="0.001 .001 0.001"/>
      </geometry>
    </visual>
    <collision>
      <origin rpy="0 0 0" xyz="0 0 0"/>
      <geometry>
        <box size="0.5845 0.526 0.2"/>
      </geometry>
    </collision>
    <!--            <collision>
                            <origin xyz="-0.033 -0.1 0.267" rpy="0 0 0.7853982"/>
                            <geometry>
                                <box size="0.0207 0.0207 0.334"/>
                            </geometry>
                        </collision>
                        <collision>
                            <origin xyz="-0.033 0.10 0.267" rpy="0 0 0.7853982"/>
                            <geometry>
                                <box size="0.0207 0.0207 0.334"/>
                            </geometry>
                        </collision>-->
    <collision>
      <origin rpy="0 0 0.7853982" xyz="-0.23225 -0.1 0.267"/>
      <geometry>
        <box size="0.0207 0.0207 0.334"/>
      </geometry>
    </collision>
    <collision>
      <origin rpy="0 0 0.7853982" xyz="-0.23225 0.1 0.267"/>
      <geometry>
        <box size="0.0207 0.0207 0.334"/>
      </geometry>
    </collision>
    <collision>
      <origin rpy="0 0 0" xyz="-0.193 -0.189 0.235"/>
      <geometry>
        <box size="0.186 0.1 0.3"/>
      </geometry>
    </collision>
    <collision>
      <origin rpy="0 0 0" xyz="-0.0623 -0.2405 0.242"/>
      <geometry>
        <box size="0.08 0.003 0.06"/>
      </geometry>
    </collision>
  </link>
  <!--  link  -->
  <link name="front_left_wheel">
    <visual>
      <geometry>
        <mesh filename="package://rm_description/meshes/common/right_threaded_mecanum_wheel.stl" scale="0.001 0.001 0.001"/>
      </geometry>
    </visual>
    <inertial>
      <mass value="0.59"/>
      <inertia ixx="1.416e-3" ixy="0.0" ixz="0.0" iyy="2.749e-3" iyz="0.0" izz="1.416e-3"/>
    </inertial>
  </link>
  <!--  joint  -->
  <joint name="front_left_wheel_joint" type="revolute">
    <axis xyz="0 1 0"/>
    <origin rpy="0 0 0" xyz="0.19 0.21 -0.109"/>
    <!--      limit not work while type="continuous"-->
    <limit effort="5" lower="-1e16" upper="1e16" velocity="50"/>
    <dynamics damping="0.0" friction="0.05"/>
    <parent link="base_link"/>
    <child link="front_left_wheel"/>
  </joint>
  <!--  link  -->
  <link name="front_left_roller_0">
    <collision>
      <geometry>
        <sphere radius="0.009"/>
      </geometry>
    </collision>
    <inertial>
      <mass value="0.036"/>
      <inertia ixx="3128e-9" ixy="0.0" ixz="0.0" iyy="3128e-9" iyz="0.0" izz="3128e-9"/>
    </inertial>
  </link>
  <joint name="front_left_roller_0_joint" type="continuous">
    <origin rpy="0 0 0" xyz="4.117874862132975e-18 0 -0.06725"/>
    <axis xyz="0.7071067811865476 -0.7071067811865476 0.0"/>
    <dynamics damping="0.0" friction="0.001"/>
    <parent link="front_left_wheel"/>
    <child link="front_left_roller_0"/>
  </joint>
  <gazebo reference="front_left_roller_0">
    <mu1 value="2000.0"/>
    <mu2 value="2000.0"/>
    <kp value="1000000.0"/>
    <kd value="100.0"/>
    <material>Gazebo/Black</material>
  </gazebo>
  <!--  link  -->
  <link name="front_left_roller_1">
    <collision>
      <geometry>
        <sphere radius="0.009"/>
      </geometry>
    </collision>
    <inertial>
      <mass value="0.036"/>
      <inertia ixx="3128e-9" ixy="0.0" ixz="0.0" iyy="3128e-9" iyz="0.0" izz="3128e-9"/>
    </inertial>
  </link>
  <joint name="front_left_roller_1_joint" type="continuous">
    <origin rpy="0 0 0" xyz="0.025754155985525513 0 -0.06212315147731336"/>
    <axis xyz="0.653200024955946 -0.7071067811865476 0.27079462217250855"/>
    <dynamics damping="0.0" friction="0.001"/>
    <parent link="front_left_wheel"/>
    <child link="front_left_roller_1"/>
  </joint>
  <gazebo reference="front_left_roller_1">
    <mu1 value="2000.0"/>
    <mu2 value="2000.0"/>
    <kp value="1000000.0"/>
    <kd value="100.0"/>
    <material>Gazebo/Black</material>
  </gazebo>
  <!--  link  -->
  <link name="front_left_roller_2">
    <collision>
      <geometry>
        <sphere radius="0.009"/>
      </geometry>
    </collision>
    <inertial>
      <mass value="0.036"/>
      <inertia ixx="3128e-9" ixy="0.0" ixz="0.0" iyy="3128e-9" iyz="0.0" izz="3128e-9"/>
    </inertial>
  </link>
  <joint name="front_left_roller_2_joint" type="continuous">
    <origin rpy="0 0 0" xyz="0.04758154151551398 0 -0.04752430333005861"/>
    <axis xyz="0.49969899116506866 -0.7071067811865476 0.5003008277312888"/>
    <dynamics damping="0.0" friction="0.001"/>
    <parent link="front_left_wheel"/>
    <child link="front_left_roller_2"/>
  </joint>
  <gazebo reference="front_left_roller_2">
    <mu1 value="2000.0"/>
    <mu2 value="2000.0"/>
    <kp value="1000000.0"/>
    <kd value="100.0"/>
    <material>Gazebo/Black</material>
  </gazebo>
  <!--  link  -->
  <link name="front_left_roller_3">
    <collision>
      <geometry>
        <sphere radius="0.009"/>
      </geometry>
    </collision>
    <inertial>
      <mass value="0.036"/>
      <inertia ixx="3128e-9" ixy="0.0" ixz="0.0" iyy="3128e-9" iyz="0.0" izz="3128e-9"/>
    </inertial>
  </link>
  <joint name="front_left_roller_3_joint" type="continuous">
    <origin rpy="0 0 0" xyz="0.062154106054395655 0 -0.02567936137404779"/>
    <axis xyz="0.2700081868271984 -0.7071067811865476 0.6535254999204613"/>
    <dynamics damping="0.0" friction="0.001"/>
    <parent link="front_left_wheel"/>
    <child link="front_left_roller_3"/>
  </joint>
  <gazebo reference="front_left_roller_3">
    <mu1 value="2000.0"/>
    <mu2 value="2000.0"/>
    <kp value="1000000.0"/>
    <kd value="100.0"/>
    <material>Gazebo/Black</material>
  </gazebo>
  <!--  link  -->
  <link name="front_left_roller_4">
    <collision>
      <geometry>
        <sphere radius="0.009"/>
      </geometry>
    </collision>
    <inertial>
      <mass value="0.036"/>
      <inertia ixx="3128e-9" ixy="0.0" ixz="0.0" iyy="3128e-9" iyz="0.0" izz="3128e-9"/>
    </inertial>
  </link>
  <joint name="front_left_roller_4_joint" type="continuous">
    <origin rpy="0 0 0" xyz="0.06724995128312455 0 8.094700349681064e-05"/>
    <axis xyz="-0.0008511252801386329 -0.7071067811865476 0.7071062689481388"/>
    <dynamics damping="0.0" friction="0.001"/>
    <parent link="front_left_wheel"/>
    <child link="front_left_roller_4"/>
  </joint>
  <gazebo reference="front_left_roller_4">
    <mu1 value="2000.0"/>
    <mu2 value="2000.0"/>
    <kp value="1000000.0"/>
    <kd value="100.0"/>
    <material>Gazebo/Black</material>
  </gazebo>
  <!--  link  -->
  <link name="front_left_roller_5">
    <collision>
      <geometry>
        <sphere radius="0.009"/>
      </geometry>
    </collision>
    <inertial>
      <mass value="0.036"/>
      <inertia ixx="3128e-9" ixy="0.0" ixz="0.0" iyy="3128e-9" iyz="0.0" izz="3128e-9"/>
    </inertial>
  </link>
  <joint name="front_left_roller_5_joint" type="continuous">
    <origin rpy="0 0 0" xyz="0.06209210689440703 0 0.025828913283634913"/>
    <axis xyz="-0.27158066518271434 -0.7071067811865476 0.6528736036162853"/>
    <dynamics damping="0.0" friction="0.001"/>
    <parent link="front_left_wheel"/>
    <child link="front_left_roller_5"/>
  </joint>
  <gazebo reference="front_left_roller_5">
    <mu1 value="2000.0"/>
    <mu2 value="2000.0"/>
    <kp value="1000000.0"/>
    <kd value="100.0"/>
    <material>Gazebo/Black</material>
  </gazebo>
  <!--  link  -->
  <link name="front_left_roller_6">
    <collision>
      <geometry>
        <sphere radius="0.009"/>
      </geometry>
    </collision>
    <inertial>
      <mass value="0.036"/>
      <inertia ixx="3128e-9" ixy="0.0" ixz="0.0" iyy="3128e-9" iyz="0.0" izz="3128e-9"/>
    </inertial>
  </link>
  <joint name="front_left_roller_6_joint" type="continuous">
    <origin rpy="0 0 0" xyz="0.04746699629001391 0 0.04763871076345167"/>
    <axis xyz="-0.5009019394471561 -0.7071067811865476 0.499096430620454"/>
    <dynamics damping="0.0" friction="0.001"/>
    <parent link="front_left_wheel"/>
    <child link="front_left_roller_6"/>
  </joint>
  <gazebo reference="front_left_roller_6">
    <mu1 value="2000.0"/>
    <mu2 value="2000.0"/>
    <kp value="1000000.0"/>
    <kd value="100.0"/>
    <material>Gazebo/Black</material>
  </gazebo>
  <!--  link  -->
  <link name="front_left_roller_7">
    <collision>
      <geometry>
        <sphere radius="0.009"/>
      </geometry>
    </collision>
    <inertial>
      <mass value="0.036"/>
      <inertia ixx="3128e-9" ixy="0.0" ixz="0.0" iyy="3128e-9" iyz="0.0" izz="3128e-9"/>
    </inertial>
  </link>
  <joint name="front_left_roller_7_joint" type="continuous">
    <origin rpy="0 0 0" xyz="0.02560452955756635 0 0.06218497058080603"/>
    <axis xyz="-0.6538500280382736 -0.7071067811865476 0.2692213602861942"/>
    <dynamics damping="0.0" friction="0.001"/>
    <parent link="front_left_wheel"/>
    <child link="front_left_roller_7"/>
  </joint>
  <gazebo reference="front_left_roller_7">
    <mu1 value="2000.0"/>
    <mu2 value="2000.0"/>
    <kp value="1000000.0"/>
    <kd value="100.0"/>
    <material>Gazebo/Black</material>
  </gazebo>
  <!--  link  -->
  <link name="front_left_roller_8">
    <collision>
      <geometry>
        <sphere radius="0.009"/>
      </geometry>
    </collision>
    <inertial>
      <mass value="0.036"/>
      <inertia ixx="3128e-9" ixy="0.0" ixz="0.0" iyy="3128e-9" iyz="0.0" izz="3128e-9"/>
    </inertial>
  </link>
  <joint name="front_left_roller_8_joint" type="continuous">
    <origin rpy="0 0 0" xyz="-0.0001618938897152502 0 0.06724980513256877"/>
    <axis xyz="-0.7071047322336546 -0.7071067811865476 -0.0017022493271422689"/>
    <dynamics damping="0.0" friction="0.001"/>
    <parent link="front_left_wheel"/>
    <child link="front_left_roller_8"/>
  </joint>
  <gazebo reference="front_left_roller_8">
    <mu1 value="2000.0"/>
    <mu2 value="2000.0"/>
    <kp value="1000000.0"/>
    <kd value="100.0"/>
    <material>Gazebo/Black</material>
  </gazebo>
  <!--  link  -->
  <link name="front_left_roller_9">
    <collision>
      <geometry>
        <sphere radius="0.009"/>
      </geometry>
    </collision>
    <inertial>
      <mass value="0.036"/>
      <inertia ixx="3128e-9" ixy="0.0" ixz="0.0" iyy="3128e-9" iyz="0.0" izz="3128e-9"/>
    </inertial>
  </link>
  <joint name="front_left_roller_9_joint" type="continuous">
    <origin rpy="0 0 0" xyz="-0.025903633160065442 0 0.062060972350654955"/>
    <axis xyz="-0.6525462363744081 -0.7071067811865476 -0.2723663147189738"/>
    <dynamics damping="0.0" friction="0.001"/>
    <parent link="front_left_wheel"/>
    <child link="front_left_roller_9"/>
  </joint>
  <gazebo reference="front_left_roller_9">
    <mu1 value="2000.0"/>
    <mu2 value="2000.0"/>
    <kp value="1000000.0"/>
    <kd value="100.0"/>
    <material>Gazebo/Black</material>
  </gazebo>
  <!--  link  -->
  <link name="front_left_roller_10">
    <collision>
      <geometry>
        <sphere radius="0.009"/>
      </geometry>
    </collision>
    <inertial>
      <mass value="0.036"/>
      <inertia ixx="3128e-9" ixy="0.0" ixz="0.0" iyy="3128e-9" iyz="0.0" izz="3128e-9"/>
    </inertial>
  </link>
  <joint name="front_left_roller_10_joint" type="continuous">
    <origin rpy="0 0 0" xyz="-0.04769581099104322 0 0.04740962047840798"/>
    <axis xyz="-0.49849314697045194 -0.7071067811865476 -0.5015023254417625"/>
    <dynamics damping="0.0" friction="0.001"/>
    <parent link="front_left_wheel"/>
    <child link="front_left_roller_10"/>
  </joint>
  <gazebo reference="front_left_roller_10">
    <mu1 value="2000.0"/>
    <mu2 value="2000.0"/>
    <kp value="1000000.0"/>
    <kd value="100.0"/>
    <material>Gazebo/Black</material>
  </gazebo>
  <!--  link  -->
  <link name="front_left_roller_11">
    <collision>
      <geometry>
        <sphere radius="0.009"/>
      </geometry>
    </collision>
    <inertial>
      <mass value="0.036"/>
      <inertia ixx="3128e-9" ixy="0.0" ixz="0.0" iyy="3128e-9" iyz="0.0" izz="3128e-9"/>
    </inertial>
  </link>
  <joint name="front_left_roller_11_joint" type="continuous">
    <origin rpy="0 0 0" xyz="-0.06221574501182705 0 0.02552966064449972"/>
    <axis xyz="-0.2684341436894733 -0.7071067811865476 -0.6541736088391974"/>
    <dynamics damping="0.0" friction="0.001"/>
    <parent link="front_left_wheel"/>
    <child link="front_left_roller_11"/>
  </joint>
  <gazebo reference="front_left_roller_11">
    <mu1 value="2000.0"/>
    <mu2 value="2000.0"/>
    <kp value="1000000.0"/>
    <kd value="100.0"/>
    <material>Gazebo/Black</material>
  </gazebo>
  <!--  link  -->
  <link name="front_left_roller_12">
    <collision>
      <geometry>
        <sphere radius="0.009"/>
      </geometry>
    </collision>
    <inertial>
      <mass value="0.036"/>
      <inertia ixx="3128e-9" ixy="0.0" ixz="0.0" iyy="3128e-9" iyz="0.0" izz="3128e-9"/>
    </inertial>
  </link>
  <joint name="front_left_roller_12_joint" type="continuous">
    <origin rpy="0 0 0" xyz="-0.06724956154854442 0 -0.00024284054137712588"/>
    <axis xyz="0.002553370907877698 -0.7071067811865476 -0.7071021710453214"/>
    <dynamics damping="0.0" friction="0.001"/>
    <parent link="front_left_wheel"/>
    <child link="front_left_roller_12"/>
  </joint>
  <gazebo reference="front_left_roller_12">
    <mu1 value="2000.0"/>
    <mu2 value="2000.0"/>
    <kp value="1000000.0"/>
    <kd value="100.0"/>
    <material>Gazebo/Black</material>
  </gazebo>
  <!--  link  -->
  <link name="front_left_roller_13">
    <collision>
      <geometry>
        <sphere radius="0.009"/>
      </geometry>
    </collision>
    <inertial>
      <mass value="0.036"/>
      <inertia ixx="3128e-9" ixy="0.0" ixz="0.0" iyy="3128e-9" iyz="0.0" izz="3128e-9"/>
    </inertial>
  </link>
  <joint name="front_left_roller_13_joint" type="continuous">
    <origin rpy="0 0 0" xyz="-0.062029747891165755 0 -0.025978315506560806"/>
    <axis xyz="0.2731515696430154 -0.7071067811865476 -0.6522179237046135"/>
    <dynamics damping="0.0" friction="0.001"/>
    <parent link="front_left_wheel"/>
    <child link="front_left_roller_13"/>
  </joint>
  <gazebo reference="front_left_roller_13">
    <mu1 value="2000.0"/>
    <mu2 value="2000.0"/>
    <kp value="1000000.0"/>
    <kd value="100.0"/>
    <material>Gazebo/Black</material>
  </gazebo>
  <!--  link  -->
  <link name="front_left_roller_14">
    <collision>
      <geometry>
        <sphere radius="0.009"/>
      </geometry>
    </collision>
    <inertial>
      <mass value="0.036"/>
      <inertia ixx="3128e-9" ixy="0.0" ixz="0.0" iyy="3128e-9" iyz="0.0" izz="3128e-9"/>
    </inertial>
  </link>
  <joint name="front_left_roller_14_joint" type="continuous">
    <origin rpy="0 0 0" xyz="-0.047352175978368535 0 -0.04775284211556018"/>
    <axis xyz="0.5021019848452515 -0.7071067811865476 -0.49788914108911725"/>
    <dynamics damping="0.0" friction="0.001"/>
    <parent link="front_left_wheel"/>
    <child link="front_left_roller_14"/>
  </joint>
  <gazebo reference="front_left_roller_14">
    <mu1 value="2000.0"/>
    <mu2 value="2000.0"/>
    <kp value="1000000.0"/>
    <kd value="100.0"/>
    <material>Gazebo/Black</material>
  </gazebo>
  <!--  link  -->
  <link name="front_left_roller_15">
    <collision>
      <geometry>
        <sphere radius="0.009"/>
      </geometry>
    </collision>
    <inertial>
      <mass value="0.036"/>
      <inertia ixx="3128e-9" ixy="0.0" ixz="0.0" iyy="3128e-9" iyz="0.0" izz="3128e-9"/>
    </inertial>
  </link>
  <joint name="front_left_roller_15_joint" type="continuous">
    <origin rpy="0 0 0" xyz="-0.025454754743320145 0 -0.06224642930287183"/>
    <axis xyz="0.6544962418544192 -0.7071067811865476 -0.2676465381775779"/>
    <dynamics damping="0.0" friction="0.001"/>
    <parent link="front_left_wheel"/>
    <child link="front_left_roller_15"/>
  </joint>
  <gazebo reference="front_left_roller_15">
    <mu1 value="2000.0"/>
    <mu2 value="2000.0"/>
    <kp value="1000000.0"/>
    <kd value="100.0"/>
    <material>Gazebo/Black</material>
  </gazebo>
  <!--  link  -->
  <link name="front_right_wheel">
    <visual>
      <geometry>
        <mesh filename="package://rm_description/meshes/common/left_threaded_mecanum_wheel.stl" scale="0.001 0.001 0.001"/>
      </geometry>
    </visual>
    <inertial>
      <mass value="0.59"/>
      <inertia ixx="1.416e-3" ixy="0.0" ixz="0.0" iyy="2.749e-3" iyz="0.0" izz="1.416e-3"/>
    </inertial>
  </link>
  <!--  joint  -->
  <joint name="front_right_wheel_joint" type="revolute">
    <axis xyz="0 1 0"/>
    <origin rpy="0 0 0" xyz="0.19 -0.21 -0.109"/>
    <!--      limit not work while type="continuous"-->
    <limit effort="5" lower="-1e16" upper="1e16" velocity="50"/>
    <dynamics damping="0.0" friction="0.05"/>
    <parent link="base_link"/>
    <child link="front_right_wheel"/>
  </joint>
  <!--  link  -->
  <link name="front_right_roller_0">
    <collision>
      <geometry>
        <sphere radius="0.009"/>
      </geometry>
    </collision>
    <inertial>
      <mass value="0.036"/>
      <inertia ixx="3128e-9" ixy="0.0" ixz="0.0" iyy="3128e-9" iyz="0.0" izz="3128e-9"/>
    </inertial>
  </link>
  <joint name="front_right_roller_0_joint" type="continuous">
    <origin rpy="0 0 0" xyz="4.117874862132975e-18 0 -0.06725"/>
    <axis xyz="0.7071067811865476 0.7071067811865476 0.0"/>
    <dynamics damping="0.0" friction="0.001"/>
    <parent link="front_right_wheel"/>
    <child link="front_right_roller_0"/>
  </joint>
  <gazebo reference="front_right_roller_0">
    <mu1 value="2000.0"/>
    <mu2 value="2000.0"/>
    <kp value="1000000.0"/>
    <kd value="100.0"/>
    <material>Gazebo/Black</material>
  </gazebo>
  <!--  link  -->
  <link name="front_right_roller_1">
    <collision>
      <geometry>
        <sphere radius="0.009"/>
      </geometry>
    </collision>
    <inertial>
      <mass value="0.036"/>
      <inertia ixx="3128e-9" ixy="0.0" ixz="0.0" iyy="3128e-9" iyz="0.0" izz="3128e-9"/>
    </inertial>
  </link>
  <joint name="front_right_roller_1_joint" type="continuous">
    <origin rpy="0 0 0" xyz="0.025754155985525513 0 -0.06212315147731336"/>
    <axis xyz="0.653200024955946 0.7071067811865476 0.27079462217250855"/>
    <dynamics damping="0.0" friction="0.001"/>
    <parent link="front_right_wheel"/>
    <child link="front_right_roller_1"/>
  </joint>
  <gazebo reference="front_right_roller_1">
    <mu1 value="2000.0"/>
    <mu2 value="2000.0"/>
    <kp value="1000000.0"/>
    <kd value="100.0"/>
    <material>Gazebo/Black</material>
  </gazebo>
  <!--  link  -->
  <link name="front_right_roller_2">
    <collision>
      <geometry>
        <sphere radius="0.009"/>
      </geometry>
    </collision>
    <inertial>
      <mass value="0.036"/>
      <inertia ixx="3128e-9" ixy="0.0" ixz="0.0" iyy="3128e-9" iyz="0.0" izz="3128e-9"/>
    </inertial>
  </link>
  <joint name="front_right_roller_2_joint" type="continuous">
    <origin rpy="0 0 0" xyz="0.04758154151551398 0 -0.04752430333005861"/>
    <axis xyz="0.49969899116506866 0.7071067811865476 0.5003008277312888"/>
    <dynamics damping="0.0" friction="0.001"/>
    <parent link="front_right_wheel"/>
    <child link="front_right_roller_2"/>
  </joint>
  <gazebo reference="front_right_roller_2">
    <mu1 value="2000.0"/>
    <mu2 value="2000.0"/>
    <kp value="1000000.0"/>
    <kd value="100.0"/>
    <material>Gazebo/Black</material>
  </gazebo>
  <!--  link  -->
  <link name="front_right_roller_3">
    <collision>
      <geometry>
        <sphere radius="0.009"/>
      </geometry>
    </collision>
    <inertial>
      <mass value="0.036"/>
      <inertia ixx="3128e-9" ixy="0.0" ixz="0.0" iyy="3128e-9" iyz="0.0" izz="3128e-9"/>
    </inertial>
  </link>
  <joint name="front_right_roller_3_joint" type="continuous">
    <origin rpy="0 0 0" xyz="0.062154106054395655 0 -0.02567936137404779"/>
    <axis xyz="0.2700081868271984 0.7071067811865476 0.6535254999204613"/>
    <dynamics damping="0.0" friction="0.001"/>
    <parent link="front_right_wheel"/>
    <child link="front_right_roller_3"/>
  </joint>
  <gazebo reference="front_right_roller_3">
    <mu1 value="2000.0"/>
    <mu2 value="2000.0"/>
    <kp value="1000000.0"/>
    <kd value="100.0"/>
    <material>Gazebo/Black</material>
  </gazebo>
  <!--  link  -->
  <link name="front_right_roller_4">
    <collision>
      <geometry>
        <sphere radius="0.009"/>
      </geometry>
    </collision>
    <inertial>
      <mass value="0.036"/>
      <inertia ixx="3128e-9" ixy="0.0" ixz="0.0" iyy="3128e-9" iyz="0.0" izz="3128e-9"/>
    </inertial>
  </link>
  <joint name="front_right_roller_4_joint" type="continuous">
    <origin rpy="0 0 0" xyz="0.06724995128312455 0 8.094700349681064e-05"/>
    <axis xyz="-0.0008511252801386329 0.7071067811865476 0.7071062689481388"/>
    <dynamics damping="0.0" friction="0.001"/>
    <parent link="front_right_wheel"/>
    <child link="front_right_roller_4"/>
  </joint>
  <gazebo reference="front_right_roller_4">
    <mu1 value="2000.0"/>
    <mu2 value="2000.0"/>
    <kp value="1000000.0"/>
    <kd value="100.0"/>
    <material>Gazebo/Black</material>
  </gazebo>
  <!--  link  -->
  <link name="front_right_roller_5">
    <collision>
      <geometry>
        <sphere radius="0.009"/>
      </geometry>
    </collision>
    <inertial>
      <mass value="0.036"/>
      <inertia ixx="3128e-9" ixy="0.0" ixz="0.0" iyy="3128e-9" iyz="0.0" izz="3128e-9"/>
    </inertial>
  </link>
  <joint name="front_right_roller_5_joint" type="continuous">
    <origin rpy="0 0 0" xyz="0.06209210689440703 0 0.025828913283634913"/>
    <axis xyz="-0.27158066518271434 0.7071067811865476 0.6528736036162853"/>
    <dynamics damping="0.0" friction="0.001"/>
    <parent link="front_right_wheel"/>
    <child link="front_right_roller_5"/>
  </joint>
  <gazebo reference="front_right_roller_5">
    <mu1 value="2000.0"/>
    <mu2 value="2000.0"/>
    <kp value="1000000.0"/>
    <kd value="100.0"/>
    <material>Gazebo/Black</material>
  </gazebo>
  <!--  link  -->
  <link name="front_right_roller_6">
    <collision>
      <geometry>
        <sphere radius="0.009"/>
      </geometry>
    </collision>
    <inertial>
      <mass value="0.036"/>
      <inertia ixx="3128e-9" ixy="0.0" ixz="0.0" iyy="3128e-9" iyz="0.0" izz="3128e-9"/>
    </inertial>
  </link>
  <joint name="front_right_roller_6_joint" type="continuous">
    <origin rpy="0 0 0" xyz="0.04746699629001391 0 0.04763871076345167"/>
    <axis xyz="-0.5009019394471561 0.7071067811865476 0.499096430620454"/>
    <dynamics damping="0.0" friction="0.001"/>
    <parent link="front_right_wheel"/>
    <child link="front_right_roller_6"/>
  </joint>
  <gazebo reference="front_right_roller_6">
    <mu1 value="2000.0"/>
    <mu2 value="2000.0"/>
    <kp value="1000000.0"/>
    <kd value="100.0"/>
    <material>Gazebo/Black</material>
  </gazebo>
  <!--  link  -->
  <link name="front_right_roller_7">
    <collision>
      <geometry>
        <sphere radius="0.009"/>
      </geometry>
    </collision>
    <inertial>
      <mass value="0.036"/>
      <inertia ixx="3128e-9" ixy="0.0" ixz="0.0" iyy="3128e-9" iyz="0.0" izz="3128e-9"/>
    </inertial>
  </link>
  <joint name="front_right_roller_7_joint" type="continuous">
    <origin rpy="0 0 0" xyz="0.02560452955756635 0 0.06218497058080603"/>
    <axis xyz="-0.6538500280382736 0.7071067811865476 0.2692213602861942"/>
    <dynamics damping="0.0" friction="0.001"/>
    <parent link="front_right_wheel"/>
    <child link="front_right_roller_7"/>
  </joint>
  <gazebo reference="front_right_roller_7">
    <mu1 value="2000.0"/>
    <mu2 value="2000.0"/>
    <kp value="1000000.0"/>
    <kd value="100.0"/>
    <material>Gazebo/Black</material>
  </gazebo>
  <!--  link  -->
  <link name="front_right_roller_8">
    <collision>
      <geometry>
        <sphere radius="0.009"/>
      </geometry>
    </collision>
    <inertial>
      <mass value="0.036"/>
      <inertia ixx="3128e-9" ixy="0.0" ixz="0.0" iyy="3128e-9" iyz="0.0" izz="3128e-9"/>
    </inertial>
  </link>
  <joint name="front_right_roller_8_joint" type="continuous">
    <origin rpy="0 0 0" xyz="-0.0001618938897152502 0 0.06724980513256877"/>
    <axis xyz="-0.7071047322336546 0.7071067811865476 -0.0017022493271422689"/>
    <dynamics damping="0.0" friction="0.001"/>
    <parent link="front_right_wheel"/>
    <child link="front_right_roller_8"/>
  </joint>
  <gazebo reference="front_right_roller_8">
    <mu1 value="2000.0"/>
    <mu2 value="2000.0"/>
    <kp value="1000000.0"/>
    <kd value="100.0"/>
    <material>Gazebo/Black</material>
  </gazebo>
  <!--  link  -->
  <link name="front_right_roller_9">
    <collision>
      <geometry>
        <sphere radius="0.009"/>
      </geometry>
    </collision>
    <inertial>
      <mass value="0.036"/>
      <inertia ixx="3128e-9" ixy="0.0" ixz="0.0" iyy="3128e-9" iyz="0.0" izz="3128e-9"/>
    </inertial>
  </link>
  <joint name="front_right_roller_9_joint" type="continuous">
    <origin rpy="0 0 0" xyz="-0.025903633160065442 0 0.062060972350654955"/>
    <axis xyz="-0.6525462363744081 0.7071067811865476 -0.2723663147189738"/>
    <dynamics damping="0.0" friction="0.001"/>
    <parent link="front_right_wheel"/>
    <child link="front_right_roller_9"/>
  </joint>
  <gazebo reference="front_right_roller_9">
    <mu1 value="2000.0"/>
    <mu2 value="2000.0"/>
    <kp value="1000000.0"/>
    <kd value="100.0"/>
    <material>Gazebo/Black</material>
  </gazebo>
  <!--  link  -->
  <link name="front_right_roller_10">
    <collision>
      <geometry>
        <sphere radius="0.009"/>
      </geometry>
    </collision>
    <inertial>
      <mass value="0.036"/>
      <inertia ixx="3128e-9" ixy="0.0" ixz="0.0" iyy="3128e-9" iyz="0.0" izz="3128e-9"/>
    </inertial>
  </link>
  <joint name="front_right_roller_10_joint" type="continuous">
    <origin rpy="0 0 0" xyz="-0.04769581099104322 0 0.04740962047840798"/>
    <axis xyz="-0.49849314697045194 0.7071067811865476 -0.5015023254417625"/>
    <dynamics damping="0.0" friction="0.001"/>
    <parent link="front_right_wheel"/>
    <child link="front_right_roller_10"/>
  </joint>
  <gazebo reference="front_right_roller_10">
    <mu1 value="2000.0"/>
    <mu2 value="2000.0"/>
    <kp value="1000000.0"/>
    <kd value="100.0"/>
    <material>Gazebo/Black</material>
  </gazebo>
  <!--  link  -->
  <link name="front_right_roller_11">
    <collision>
      <geometry>
        <sphere radius="0.009"/>
      </geometry>
    </collision>
    <inertial>
      <mass value="0.036"/>
      <inertia ixx="3128e-9" ixy="0.0" ixz="0.0" iyy="3128e-9" iyz="0.0" izz="3128e-9"/>
    </inertial>
  </link>
  <joint name="front_right_roller_11_joint" type="continuous">
    <origin rpy="0 0 0" xyz="-0.06221574501182705 0 0.02552966064449972"/>
    <axis xyz="-0.2684341436894733 0.7071067811865476 -0.6541736088391974"/>
    <dynamics damping="0.0" friction="0.001"/>
    <parent link="front_right_wheel"/>
    <child link="front_right_roller_11"/>
  </joint>
  <gazebo reference="front_right_roller_11">
    <mu1 value="2000.0"/>
    <mu2 value="2000.0"/>
    <kp value="1000000.0"/>
    <kd value="100.0"/>
    <material>Gazebo/Black</material>
  </gazebo>
  <!--  link  -->
  <link name="front_right_roller_12">
    <collision>
      <geometry>
        <sphere radius="0.009"/>
      </geometry>
    </collision>
    <inertial>
      <mass value="0.036"/>
      <inertia ixx="3128e-9" ixy="0.0" ixz="0.0" iyy="3128e-9" iyz="0.0" izz="3128e-9"/>
    </inertial>
  </link>
  <joint name="front_right_roller_12_joint" type="continuous">
    <origin rpy="0 0 0" xyz="-0.06724956154854442 0 -0.00024284054137712588"/>
    <axis xyz="0.002553370907877698 0.7071067811865476 -0.7071021710453214"/>
    <dynamics damping="0.0" friction="0.001"/>
    <parent link="front_right_wheel"/>
    <child link="front_right_roller_12"/>
  </joint>
  <gazebo reference="front_right_roller_12">
    <mu1 value="2000.0"/>
    <mu2 value="2000.0"/>
    <kp value="1000000.0"/>
    <kd value="100.0"/>
    <material>Gazebo/Black</material>
  </gazebo>
  <!--  link  -->
  <link name="front_right_roller_13">
    <collision>
      <geometry>
        <sphere radius="0.009"/>
      </geometry>
    </collision>
    <inertial>
      <mass value="0.036"/>
      <inertia ixx="3128e-9" ixy="0.0" ixz="0.0" iyy="3128e-9" iyz="0.0" izz="3128e-9"/>
    </inertial>
  </link>
  <joint name="front_right_roller_13_joint" type="continuous">
    <origin rpy="0 0 0" xyz="-0.062029747891165755 0 -0.025978315506560806"/>
    <axis xyz="0.2731515696430154 0.7071067811865476 -0.6522179237046135"/>
    <dynamics damping="0.0" friction="0.001"/>
    <parent link="front_right_wheel"/>
    <child link="front_right_roller_13"/>
  </joint>
  <gazebo reference="front_right_roller_13">
    <mu1 value="2000.0"/>
    <mu2 value="2000.0"/>
    <kp value="1000000.0"/>
    <kd value="100.0"/>
    <material>Gazebo/Black</material>
  </gazebo>
  <!--  link  -->
  <link name="front_right_roller_14">
    <collision>
      <geometry>
        <sphere radius="0.009"/>
      </geometry>
    </collision>
    <inertial>
      <mass value="0.036"/>
      <inertia ixx="3128e-9" ixy="0.0" ixz="0.0" iyy="3128e-9" iyz="0.0" izz="3128e-9"/>
    </inertial>
  </link>
  <joint name="front_right_roller_14_joint" type="continuous">
    <origin rpy="0 0 0" xyz="-0.047352175978368535 0 -0.04775284211556018"/>
    <axis xyz="0.5021019848452515 0.7071067811865476 -0.49788914108911725"/>
    <dynamics damping="0.0" friction="0.001"/>
    <parent link="front_right_wheel"/>
    <child link="front_right_roller_14"/>
  </joint>
  <gazebo reference="front_right_roller_14">
    <mu1 value="2000.0"/>
    <mu2 value="2000.0"/>
    <kp value="1000000.0"/>
    <kd value="100.0"/>
    <material>Gazebo/Black</material>
  </gazebo>
  <!--  link  -->
  <link name="front_right_roller_15">
    <collision>
      <geometry>
        <sphere radius="0.009"/>
      </geometry>
    </collision>
    <inertial>
      <mass value="0.036"/>
      <inertia ixx="3128e-9" ixy="0.0" ixz="0.0" iyy="3128e-9" iyz="0.0" izz="3128e-9"/>
    </inertial>
  </link>
  <joint name="front_right_roller_15_joint" type="continuous">
    <origin rpy="0 0 0" xyz="-0.025454754743320145 0 -0.06224642930287183"/>
    <axis xyz="0.6544962418544192 0.7071067811865476 -0.2676465381775779"/>
    <dynamics damping="0.0" friction="0.001"/>
    <parent link="front_right_wheel"/>
    <child link="front_right_roller_15"/>
  </joint>
  <gazebo reference="front_right_roller_15">
    <mu1 value="2000.0"/>
    <mu2 value="2000.0"/>
    <kp value="1000000.0"/>
    <kd value="100.0"/>
    <material>Gazebo/Black</material>
  </gazebo>
  <!--  link  -->
  <link name="back_left_wheel">
    <visual>
      <geometry>
        <mesh filename="package://rm_description/meshes/common/left_threaded_mecanum_wheel.stl" scale="0.001 0.001 0.001"/>
      </geometry>
    </visual>
    <inertial>
      <mass value="0.59"/>
      <inertia ixx="1.416e-3" ixy="0.0" ixz="0.0" iyy="2.749e-3" iyz="0.0" izz="1.416e-3"/>
    </inertial>
  </link>
  <!--  joint  -->
  <joint name="back_left_wheel_joint" type="revolute">
    <axis xyz="0 1 0"/>
    <origin rpy="0 0 0" xyz="-0.19 0.21 -0.109"/>
    <!--      limit not work while type="continuous"-->
    <limit effort="5" lower="-1e16" upper="1e16" velocity="50"/>
    <dynamics damping="0.0" friction="0.05"/>
    <parent link="base_link"/>
    <child link="back_left_wheel"/>
  </joint>
  <!--  link  -->
  <link name="back_left_roller_0">
    <collision>
      <geometry>
        <sphere radius="0.009"/>
      </geometry>
    </collision>
    <inertial>
      <mass value="0.036"/>
      <inertia ixx="3128e-9" ixy="0.0" ixz="0.0" iyy="3128e-9" iyz="0.0" izz="3128e-9"/>
    </inertial>
  </link>
  <joint name="back_left_roller_0_joint" type="continuous">
    <origin rpy="0 0 0" xyz="4.117874862132975e-18 0 -0.06725"/>
    <axis xyz="0.7071067811865476 0.7071067811865476 0.0"/>
    <dynamics damping="0.0" friction="0.001"/>
    <parent link="back_left_wheel"/>
    <child link="back_left_roller_0"/>
  </joint>
  <gazebo reference="back_left_roller_0">
    <mu1 value="2000.0"/>
    <mu2 value="2000.0"/>
    <kp value="1000000.0"/>
    <kd value="100.0"/>
    <material>Gazebo/Black</material>
  </gazebo>
  <!--  link  -->
  <link name="back_left_roller_1">
    <collision>
      <geometry>
        <sphere radius="0.009"/>
      </geometry>
    </collision>
    <inertial>
      <mass value="0.036"/>
      <inertia ixx="3128e-9" ixy="0.0" ixz="0.0" iyy="3128e-9" iyz="0.0" izz="3128e-9"/>
    </inertial>
  </link>
  <joint name="back_left_roller_1_joint" type="continuous">
    <origin rpy="0 0 0" xyz="0.025754155985525513 0 -0.06212315147731336"/>
    <axis xyz="0.653200024955946 0.7071067811865476 0.27079462217250855"/>
    <dynamics damping="0.0" friction="0.001"/>
    <parent link="back_left_wheel"/>
    <child link="back_left_roller_1"/>
  </joint>
  <gazebo reference="back_left_roller_1">
    <mu1 value="2000.0"/>
    <mu2 value="2000.0"/>
    <kp value="1000000.0"/>
    <kd value="100.0"/>
    <material>Gazebo/Black</material>
  </gazebo>
  <!--  link  -->
  <link name="back_left_roller_2">
    <collision>
      <geometry>
        <sphere radius="0.009"/>
      </geometry>
    </collision>
    <inertial>
      <mass value="0.036"/>
      <inertia ixx="3128e-9" ixy="0.0" ixz="0.0" iyy="3128e-9" iyz="0.0" izz="3128e-9"/>
    </inertial>
  </link>
  <joint name="back_left_roller_2_joint" type="continuous">
    <origin rpy="0 0 0" xyz="0.04758154151551398 0 -0.04752430333005861"/>
    <axis xyz="0.49969899116506866 0.7071067811865476 0.5003008277312888"/>
    <dynamics damping="0.0" friction="0.001"/>
    <parent link="back_left_wheel"/>
    <child link="back_left_roller_2"/>
  </joint>
  <gazebo reference="back_left_roller_2">
    <mu1 value="2000.0"/>
    <mu2 value="2000.0"/>
    <kp value="1000000.0"/>
    <kd value="100.0"/>
    <material>Gazebo/Black</material>
  </gazebo>
  <!--  link  -->
  <link name="back_left_roller_3">
    <collision>
      <geometry>
        <sphere radius="0.009"/>
      </geometry>
    </collision>
    <inertial>
      <mass value="0.036"/>
      <inertia ixx="3128e-9" ixy="0.0" ixz="0.0" iyy="3128e-9" iyz="0.0" izz="3128e-9"/>
    </inertial>
  </link>
  <joint name="back_left_roller_3_joint" type="continuous">
    <origin rpy="0 0 0" xyz="0.062154106054395655 0 -0.02567936137404779"/>
    <axis xyz="0.2700081868271984 0.7071067811865476 0.6535254999204613"/>
    <dynamics damping="0.0" friction="0.001"/>
    <parent link="back_left_wheel"/>
    <child link="back_left_roller_3"/>
  </joint>
  <gazebo reference="back_left_roller_3">
    <mu1 value="2000.0"/>
    <mu2 value="2000.0"/>
    <kp value="1000000.0"/>
    <kd value="100.0"/>
    <material>Gazebo/Black</material>
  </gazebo>
  <!--  link  -->
  <link name="back_left_roller_4">
    <collision>
      <geometry>
        <sphere radius="0.009"/>
      </geometry>
    </collision>
    <inertial>
      <mass value="0.036"/>
      <inertia ixx="3128e-9" ixy="0.0" ixz="0.0" iyy="3128e-9" iyz="0.0" izz="3128e-9"/>
    </inertial>
  </link>
  <joint name="back_left_roller_4_joint" type="continuous">
    <origin rpy="0 0 0" xyz="0.06724995128312455 0 8.094700349681064e-05"/>
    <axis xyz="-0.0008511252801386329 0.7071067811865476 0.7071062689481388"/>
    <dynamics damping="0.0" friction="0.001"/>
    <parent link="back_left_wheel"/>
    <child link="back_left_roller_4"/>
  </joint>
  <gazebo reference="back_left_roller_4">
    <mu1 value="2000.0"/>
    <mu2 value="2000.0"/>
    <kp value="1000000.0"/>
    <kd value="100.0"/>
    <material>Gazebo/Black</material>
  </gazebo>
  <!--  link  -->
  <link name="back_left_roller_5">
    <collision>
      <geometry>
        <sphere radius="0.009"/>
      </geometry>
    </collision>
    <inertial>
      <mass value="0.036"/>
      <inertia ixx="3128e-9" ixy="0.0" ixz="0.0" iyy="3128e-9" iyz="0.0" izz="3128e-9"/>
    </inertial>
  </link>
  <joint name="back_left_roller_5_joint" type="continuous">
    <origin rpy="0 0 0" xyz="0.06209210689440703 0 0.025828913283634913"/>
    <axis xyz="-0.27158066518271434 0.7071067811865476 0.6528736036162853"/>
    <dynamics damping="0.0" friction="0.001"/>
    <parent link="back_left_wheel"/>
    <child link="back_left_roller_5"/>
  </joint>
  <gazebo reference="back_left_roller_5">
    <mu1 value="2000.0"/>
    <mu2 value="2000.0"/>
    <kp value="1000000.0"/>
    <kd value="100.0"/>
    <material>Gazebo/Black</material>
  </gazebo>
  <!--  link  -->
  <link name="back_left_roller_6">
    <collision>
      <geometry>
        <sphere radius="0.009"/>
      </geometry>
    </collision>
    <inertial>
      <mass value="0.036"/>
      <inertia ixx="3128e-9" ixy="0.0" ixz="0.0" iyy="3128e-9" iyz="0.0" izz="3128e-9"/>
    </inertial>
  </link>
  <joint name="back_left_roller_6_joint" type="continuous">
    <origin rpy="0 0 0" xyz="0.04746699629001391 0 0.04763871076345167"/>
    <axis xyz="-0.5009019394471561 0.7071067811865476 0.499096430620454"/>
    <dynamics damping="0.0" friction="0.001"/>
    <parent link="back_left_wheel"/>
    <child link="back_left_roller_6"/>
  </joint>
  <gazebo reference="back_left_roller_6">
    <mu1 value="2000.0"/>
    <mu2 value="2000.0"/>
    <kp value="1000000.0"/>
    <kd value="100.0"/>
    <material>Gazebo/Black</material>
  </gazebo>
  <!--  link  -->
  <link name="back_left_roller_7">
    <collision>
      <geometry>
        <sphere radius="0.009"/>
      </geometry>
    </collision>
    <inertial>
      <mass value="0.036"/>
      <inertia ixx="3128e-9" ixy="0.0" ixz="0.0" iyy="3128e-9" iyz="0.0" izz="3128e-9"/>
    </inertial>
  </link>
  <joint name="back_left_roller_7_joint" type="continuous">
    <origin rpy="0 0 0" xyz="0.02560452955756635 0 0.06218497058080603"/>
    <axis xyz="-0.6538500280382736 0.7071067811865476 0.2692213602861942"/>
    <dynamics damping="0.0" friction="0.001"/>
    <parent link="back_left_wheel"/>
    <child link="back_left_roller_7"/>
  </joint>
  <gazebo reference="back_left_roller_7">
    <mu1 value="2000.0"/>
    <mu2 value="2000.0"/>
    <kp value="1000000.0"/>
    <kd value="100.0"/>
    <material>Gazebo/Black</material>
  </gazebo>
  <!--  link  -->
  <link name="back_left_roller_8">
    <collision>
      <geometry>
        <sphere radius="0.009"/>
      </geometry>
    </collision>
    <inertial>
      <mass value="0.036"/>
      <inertia ixx="3128e-9" ixy="0.0" ixz="0.0" iyy="3128e-9" iyz="0.0" izz="3128e-9"/>
    </inertial>
  </link>
  <joint name="back_left_roller_8_joint" type="continuous">
    <origin rpy="0 0 0" xyz="-0.0001618938897152502 0 0.06724980513256877"/>
    <axis xyz="-0.7071047322336546 0.7071067811865476 -0.0017022493271422689"/>
    <dynamics damping="0.0" friction="0.001"/>
    <parent link="back_left_wheel"/>
    <child link="back_left_roller_8"/>
  </joint>
  <gazebo reference="back_left_roller_8">
    <mu1 value="2000.0"/>
    <mu2 value="2000.0"/>
    <kp value="1000000.0"/>
    <kd value="100.0"/>
    <material>Gazebo/Black</material>
  </gazebo>
  <!--  link  -->
  <link name="back_left_roller_9">
    <collision>
      <geometry>
        <sphere radius="0.009"/>
      </geometry>
    </collision>
    <inertial>
      <mass value="0.036"/>
      <inertia ixx="3128e-9" ixy="0.0" ixz="0.0" iyy="3128e-9" iyz="0.0" izz="3128e-9"/>
    </inertial>
  </link>
  <joint name="back_left_roller_9_joint" type="continuous">
    <origin rpy="0 0 0" xyz="-0.025903633160065442 0 0.062060972350654955"/>
    <axis xyz="-0.6525462363744081 0.7071067811865476 -0.2723663147189738"/>
    <dynamics damping="0.0" friction="0.001"/>
    <parent link="back_left_wheel"/>
    <child link="back_left_roller_9"/>
  </joint>
  <gazebo reference="back_left_roller_9">
    <mu1 value="2000.0"/>
    <mu2 value="2000.0"/>
    <kp value="1000000.0"/>
    <kd value="100.0"/>
    <material>Gazebo/Black</material>
  </gazebo>
  <!--  link  -->
  <link name="back_left_roller_10">
    <collision>
      <geometry>
        <sphere radius="0.009"/>
      </geometry>
    </collision>
    <inertial>
      <mass value="0.036"/>
      <inertia ixx="3128e-9" ixy="0.0" ixz="0.0" iyy="3128e-9" iyz="0.0" izz="3128e-9"/>
    </inertial>
  </link>
  <joint name="back_left_roller_10_joint" type="continuous">
    <origin rpy="0 0 0" xyz="-0.04769581099104322 0 0.04740962047840798"/>
    <axis xyz="-0.49849314697045194 0.7071067811865476 -0.5015023254417625"/>
    <dynamics damping="0.0" friction="0.001"/>
    <parent link="back_left_wheel"/>
    <child link="back_left_roller_10"/>
  </joint>
  <gazebo reference="back_left_roller_10">
    <mu1 value="2000.0"/>
    <mu2 value="2000.0"/>
    <kp value="1000000.0"/>
    <kd value="100.0"/>
    <material>Gazebo/Black</material>
  </gazebo>
  <!--  link  -->
  <link name="back_left_roller_11">
    <collision>
      <geometry>
        <sphere radius="0.009"/>
      </geometry>
    </collision>
    <inertial>
      <mass value="0.036"/>
      <inertia ixx="3128e-9" ixy="0.0" ixz="0.0" iyy="3128e-9" iyz="0.0" izz="3128e-9"/>
    </inertial>
  </link>
  <joint name="back_left_roller_11_joint" type="continuous">
    <origin rpy="0 0 0" xyz="-0.06221574501182705 0 0.02552966064449972"/>
    <axis xyz="-0.2684341436894733 0.7071067811865476 -0.6541736088391974"/>
    <dynamics damping="0.0" friction="0.001"/>
    <parent link="back_left_wheel"/>
    <child link="back_left_roller_11"/>
  </joint>
  <gazebo reference="back_left_roller_11">
    <mu1 value="2000.0"/>
    <mu2 value="2000.0"/>
    <kp value="1000000.0"/>
    <kd value="100.0"/>
    <material>Gazebo/Black</material>
  </gazebo>
  <!--  link  -->
  <link name="back_left_roller_12">
    <collision>
      <geometry>
        <sphere radius="0.009"/>
      </geometry>
    </collision>
    <inertial>
      <mass value="0.036"/>
      <inertia ixx="3128e-9" ixy="0.0" ixz="0.0" iyy="3128e-9" iyz="0.0" izz="3128e-9"/>
    </inertial>
  </link>
  <joint name="back_left_roller_12_joint" type="continuous">
    <origin rpy="0 0 0" xyz="-0.06724956154854442 0 -0.00024284054137712588"/>
    <axis xyz="0.002553370907877698 0.7071067811865476 -0.7071021710453214"/>
    <dynamics damping="0.0" friction="0.001"/>
    <parent link="back_left_wheel"/>
    <child link="back_left_roller_12"/>
  </joint>
  <gazebo reference="back_left_roller_12">
    <mu1 value="2000.0"/>
    <mu2 value="2000.0"/>
    <kp value="1000000.0"/>
    <kd value="100.0"/>
    <material>Gazebo/Black</material>
  </gazebo>
  <!--  link  -->
  <link name="back_left_roller_13">
    <collision>
      <geometry>
        <sphere radius="0.009"/>
      </geometry>
    </collision>
    <inertial>
      <mass value="0.036"/>
      <inertia ixx="3128e-9" ixy="0.0" ixz="0.0" iyy="3128e-9" iyz="0.0" izz="3128e-9"/>
    </inertial>
  </link>
  <joint name="back_left_roller_13_joint" type="continuous">
    <origin rpy="0 0 0" xyz="-0.062029747891165755 0 -0.025978315506560806"/>
    <axis xyz="0.2731515696430154 0.7071067811865476 -0.6522179237046135"/>
    <dynamics damping="0.0" friction="0.001"/>
    <parent link="back_left_wheel"/>
    <child link="back_left_roller_13"/>
  </joint>
  <gazebo reference="back_left_roller_13">
    <mu1 value="2000.0"/>
    <mu2 value="2000.0"/>
    <kp value="1000000.0"/>
    <kd value="100.0"/>
    <material>Gazebo/Black</material>
  </gazebo>
  <!--  link  -->
  <link name="back_left_roller_14">
    <collision>
      <geometry>
        <sphere radius="0.009"/>
      </geometry>
    </collision>
    <inertial>
      <mass value="0.036"/>
      <inertia ixx="3128e-9" ixy="0.0" ixz="0.0" iyy="3128e-9" iyz="0.0" izz="3128e-9"/>
    </inertial>
  </link>
  <joint name="back_left_roller_14_joint" type="continuous">
    <origin rpy="0 0 0" xyz="-0.047352175978368535 0 -0.04775284211556018"/>
    <axis xyz="0.5021019848452515 0.7071067811865476 -0.49788914108911725"/>
    <dynamics damping="0.0" friction="0.001"/>
    <parent link="back_left_wheel"/>
    <child link="back_left_roller_14"/>
  </joint>
  <gazebo reference="back_left_roller_14">
    <mu1 value="2000.0"/>
    <mu2 value="2000.0"/>
    <kp value="1000000.0"/>
    <kd value="100.0"/>
    <material>Gazebo/Black</material>
  </gazebo>
  <!--  link  -->
  <link name="back_left_roller_15">
    <collision>
      <geometry>
        <sphere radius="0.009"/>
      </geometry>
    </collision>
    <inertial>
      <mass value="0.036"/>
      <inertia ixx="3128e-9" ixy="0.0" ixz="0.0" iyy="3128e-9" iyz="0.0" izz="3128e-9"/>
    </inertial>
  </link>
  <joint name="back_left_roller_15_joint" type="continuous">
    <origin rpy="0 0 0" xyz="-0.025454754743320145 0 -0.06224642930287183"/>
    <axis xyz="0.6544962418544192 0.7071067811865476 -0.2676465381775779"/>
    <dynamics damping="0.0" friction="0.001"/>
    <parent link="back_left_wheel"/>
    <child link="back_left_roller_15"/>
  </joint>
  <gazebo reference="back_left_roller_15">
    <mu1 value="2000.0"/>
    <mu2 value="2000.0"/>
    <kp value="1000000.0"/>
    <kd value="100.0"/>
    <material>Gazebo/Black</material>
  </gazebo>
  <!--  link  -->
  <link name="back_right_wheel">
    <visual>
      <geometry>
        <mesh filename="package://rm_description/meshes/common/right_threaded_mecanum_wheel.stl" scale="0.001 0.001 0.001"/>
      </geometry>
    </visual>
    <inertial>
      <mass value="0.59"/>
      <inertia ixx="1.416e-3" ixy="0.0" ixz="0.0" iyy="2.749e-3" iyz="0.0" izz="1.416e-3"/>
    </inertial>
  </link>
  <!--  joint  -->
  <joint name="back_right_wheel_joint" type="revolute">
    <axis xyz="0 1 0"/>
    <origin rpy="0 0 0" xyz="-0.19 -0.21 -0.109"/>
    <!--      limit not work while type="continuous"-->
    <limit effort="5" lower="-1e16" upper="1e16" velocity="50"/>
    <dynamics damping="0.0" friction="0.05"/>
    <parent link="base_link"/>
    <child link="back_right_wheel"/>
  </joint>
  <!--  link  -->
  <link name="back_right_roller_0">
    <collision>
      <geometry>
        <sphere radius="0.009"/>
      </geometry>
    </collision>
    <inertial>
      <mass value="0.036"/>
      <inertia ixx="3128e-9" ixy="0.0" ixz="0.0" iyy="3128e-9" iyz="0.0" izz="3128e-9"/>
    </inertial>
  </link>
  <joint name="back_right_roller_0_joint" type="continuous">
    <origin rpy="0 0 0" xyz="4.117874862132975e-18 0 -0.06725"/>
    <axis xyz="0.7071067811865476 -0.7071067811865476 0.0"/>
    <dynamics damping="0.0" friction="0.001"/>
    <parent link="back_right_wheel"/>
    <child link="back_right_roller_0"/>
  </joint>
  <gazebo reference="back_right_roller_0">
    <mu1 value="2000.0"/>
    <mu2 value="2000.0"/>
    <kp value="1000000.0"/>
    <kd value="100.0"/>
    <material>Gazebo/Black</material>
  </gazebo>
  <!--  link  -->
  <link name="back_right_roller_1">
    <collision>
      <geometry>
        <sphere radius="0.009"/>
      </geometry>
    </collision>
    <inertial>
      <mass value="0.036"/>
      <inertia ixx="3128e-9" ixy="0.0" ixz="0.0" iyy="3128e-9" iyz="0.0" izz="3128e-9"/>
    </inertial>
  </link>
  <joint name="back_right_roller_1_joint" type="continuous">
    <origin rpy="0 0 0" xyz="0.025754155985525513 0 -0.06212315147731336"/>
    <axis xyz="0.653200024955946 -0.7071067811865476 0.27079462217250855"/>
    <dynamics damping="0.0" friction="0.001"/>
    <parent link="back_right_wheel"/>
    <child link="back_right_roller_1"/>
  </joint>
  <gazebo reference="back_right_roller_1">
    <mu1 value="2000.0"/>
    <mu2 value="2000.0"/>
    <kp value="1000000.0"/>
    <kd value="100.0"/>
    <material>Gazebo/Black</material>
  </gazebo>
  <!--  link  -->
  <link name="back_right_roller_2">
    <collision>
      <geometry>
        <sphere radius="0.009"/>
      </geometry>
    </collision>
    <inertial>
      <mass value="0.036"/>
      <inertia ixx="3128e-9" ixy="0.0" ixz="0.0" iyy="3128e-9" iyz="0.0" izz="3128e-9"/>
    </inertial>
  </link>
  <joint name="back_right_roller_2_joint" type="continuous">
    <origin rpy="0 0 0" xyz="0.04758154151551398 0 -0.04752430333005861"/>
    <axis xyz="0.49969899116506866 -0.7071067811865476 0.5003008277312888"/>
    <dynamics damping="0.0" friction="0.001"/>
    <parent link="back_right_wheel"/>
    <child link="back_right_roller_2"/>
  </joint>
  <gazebo reference="back_right_roller_2">
    <mu1 value="2000.0"/>
    <mu2 value="2000.0"/>
    <kp value="1000000.0"/>
    <kd value="100.0"/>
    <material>Gazebo/Black</material>
  </gazebo>
  <!--  link  -->
  <link name="back_right_roller_3">
    <collision>
      <geometry>
        <sphere radius="0.009"/>
      </geometry>
    </collision>
    <inertial>
      <mass value="0.036"/>
      <inertia ixx="3128e-9" ixy="0.0" ixz="0.0" iyy="3128e-9" iyz="0.0" izz="3128e-9"/>
    </inertial>
  </link>
  <joint name="back_right_roller_3_joint" type="continuous">
    <origin rpy="0 0 0" xyz="0.062154106054395655 0 -0.02567936137404779"/>
    <axis xyz="0.2700081868271984 -0.7071067811865476 0.6535254999204613"/>
    <dynamics damping="0.0" friction="0.001"/>
    <parent link="back_right_wheel"/>
    <child link="back_right_roller_3"/>
  </joint>
  <gazebo reference="back_right_roller_3">
    <mu1 value="2000.0"/>
    <mu2 value="2000.0"/>
    <kp value="1000000.0"/>
    <kd value="100.0"/>
    <material>Gazebo/Black</material>
  </gazebo>
  <!--  link  -->
  <link name="back_right_roller_4">
    <collision>
      <geometry>
        <sphere radius="0.009"/>
      </geometry>
    </collision>
    <inertial>
      <mass value="0.036"/>
      <inertia ixx="3128e-9" ixy="0.0" ixz="0.0" iyy="3128e-9" iyz="0.0" izz="3128e-9"/>
    </inertial>
  </link>
  <joint name="back_right_roller_4_joint" type="continuous">
    <origin rpy="0 0 0" xyz="0.06724995128312455 0 8.094700349681064e-05"/>
    <axis xyz="-0.0008511252801386329 -0.7071067811865476 0.7071062689481388"/>
    <dynamics damping="0.0" friction="0.001"/>
    <parent link="back_right_wheel"/>
    <child link="back_right_roller_4"/>
  </joint>
  <gazebo reference="back_right_roller_4">
    <mu1 value="2000.0"/>
    <mu2 value="2000.0"/>
    <kp value="1000000.0"/>
    <kd value="100.0"/>
    <material>Gazebo/Black</material>
  </gazebo>
  <!--  link  -->
  <link name="back_right_roller_5">
    <collision>
      <geometry>
        <sphere radius="0.009"/>
      </geometry>
    </collision>
    <inertial>
      <mass value="0.036"/>
      <inertia ixx="3128e-9" ixy="0.0" ixz="0.0" iyy="3128e-9" iyz="0.0" izz="3128e-9"/>
    </inertial>
  </link>
  <joint name="back_right_roller_5_joint" type="continuous">
    <origin rpy="0 0 0" xyz="0.06209210689440703 0 0.025828913283634913"/>
    <axis xyz="-0.27158066518271434 -0.7071067811865476 0.6528736036162853"/>
    <dynamics damping="0.0" friction="0.001"/>
    <parent link="back_right_wheel"/>
    <child link="back_right_roller_5"/>
  </joint>
  <gazebo reference="back_right_roller_5">
    <mu1 value="2000.0"/>
    <mu2 value="2000.0"/>
    <kp value="1000000.0"/>
    <kd value="100.0"/>
    <material>Gazebo/Black</material>
  </gazebo>
  <!--  link  -->
  <link name="back_right_roller_6">
    <collision>
      <geometry>
        <sphere radius="0.009"/>
      </geometry>
    </collision>
    <inertial>
      <mass value="0.036"/>
      <inertia ixx="3128e-9" ixy="0.0" ixz="0.0" iyy="3128e-9" iyz="0.0" izz="3128e-9"/>
    </inertial>
  </link>
  <joint name="back_right_roller_6_joint" type="continuous">
    <origin rpy="0 0 0" xyz="0.04746699629001391 0 0.04763871076345167"/>
    <axis xyz="-0.5009019394471561 -0.7071067811865476 0.499096430620454"/>
    <dynamics damping="0.0" friction="0.001"/>
    <parent link="back_right_wheel"/>
    <child link="back_right_roller_6"/>
  </joint>
  <gazebo reference="back_right_roller_6">
    <mu1 value="2000.0"/>
    <mu2 value="2000.0"/>
    <kp value="1000000.0"/>
    <kd value="100.0"/>
    <material>Gazebo/Black</material>
  </gazebo>
  <!--  link  -->
  <link name="back_right_roller_7">
    <collision>
      <geometry>
        <sphere radius="0.009"/>
      </geometry>
    </collision>
    <inertial>
      <mass value="0.036"/>
      <inertia ixx="3128e-9" ixy="0.0" ixz="0.0" iyy="3128e-9" iyz="0.0" izz="3128e-9"/>
    </inertial>
  </link>
  <joint name="back_right_roller_7_joint" type="continuous">
    <origin rpy="0 0 0" xyz="0.02560452955756635 0 0.06218497058080603"/>
    <axis xyz="-0.6538500280382736 -0.7071067811865476 0.2692213602861942"/>
    <dynamics damping="0.0" friction="0.001"/>
    <parent link="back_right_wheel"/>
    <child link="back_right_roller_7"/>
  </joint>
  <gazebo reference="back_right_roller_7">
    <mu1 value="2000.0"/>
    <mu2 value="2000.0"/>
    <kp value="1000000.0"/>
    <kd value="100.0"/>
    <material>Gazebo/Black</material>
  </gazebo>
  <!--  link  -->
  <link name="back_right_roller_8">
    <collision>
      <geometry>
        <sphere radius="0.009"/>
      </geometry>
    </collision>
    <inertial>
      <mass value="0.036"/>
      <inertia ixx="3128e-9" ixy="0.0" ixz="0.0" iyy="3128e-9" iyz="0.0" izz="3128e-9"/>
    </inertial>
  </link>
  <joint name="back_right_roller_8_joint" type="continuous">
    <origin rpy="0 0 0" xyz="-0.0001618938897152502 0 0.06724980513256877"/>
    <axis xyz="-0.7071047322336546 -0.7071067811865476 -0.0017022493271422689"/>
    <dynamics damping="0.0" friction="0.001"/>
    <parent link="back_right_wheel"/>
    <child link="back_right_roller_8"/>
  </joint>
  <gazebo reference="back_right_roller_8">
    <mu1 value="2000.0"/>
    <mu2 value="2000.0"/>
    <kp value="1000000.0"/>
    <kd value="100.0"/>
    <material>Gazebo/Black</material>
  </gazebo>
  <!--  link  -->
  <link name="back_right_roller_9">
    <collision>
      <geometry>
        <sphere radius="0.009"/>
      </geometry>
    </collision>
    <inertial>
      <mass value="0.036"/>
      <inertia ixx="3128e-9" ixy="0.0" ixz="0.0" iyy="3128e-9" iyz="0.0" izz="3128e-9"/>
    </inertial>
  </link>
  <joint name="back_right_roller_9_joint" type="continuous">
    <origin rpy="0 0 0" xyz="-0.025903633160065442 0 0.062060972350654955"/>
    <axis xyz="-0.6525462363744081 -0.7071067811865476 -0.2723663147189738"/>
    <dynamics damping="0.0" friction="0.001"/>
    <parent link="back_right_wheel"/>
    <child link="back_right_roller_9"/>
  </joint>
  <gazebo reference="back_right_roller_9">
    <mu1 value="2000.0"/>
    <mu2 value="2000.0"/>
    <kp value="1000000.0"/>
    <kd value="100.0"/>
    <material>Gazebo/Black</material>
  </gazebo>
  <!--  link  -->
  <link name="back_right_roller_10">
    <collision>
      <geometry>
        <sphere radius="0.009"/>
      </geometry>
    </collision>
    <inertial>
      <mass value="0.036"/>
      <inertia ixx="3128e-9" ixy="0.0" ixz="0.0" iyy="3128e-9" iyz="0.0" izz="3128e-9"/>
    </inertial>
  </link>
  <joint name="back_right_roller_10_joint" type="continuous">
    <origin rpy="0 0 0" xyz="-0.04769581099104322 0 0.04740962047840798"/>
    <axis xyz="-0.49849314697045194 -0.7071067811865476 -0.5015023254417625"/>
    <dynamics damping="0.0" friction="0.001"/>
    <parent link="back_right_wheel"/>
    <child link="back_right_roller_10"/>
  </joint>
  <gazebo reference="back_right_roller_10">
    <mu1 value="2000.0"/>
    <mu2 value="2000.0"/>
    <kp value="1000000.0"/>
    <kd value="100.0"/>
    <material>Gazebo/Black</material>
  </gazebo>
  <!--  link  -->
  <link name="back_right_roller_11">
    <collision>
      <geometry>
        <sphere radius="0.009"/>
      </geometry>
    </collision>
    <inertial>
      <mass value="0.036"/>
      <inertia ixx="3128e-9" ixy="0.0" ixz="0.0" iyy="3128e-9" iyz="0.0" izz="3128e-9"/>
    </inertial>
  </link>
  <joint name="back_right_roller_11_joint" type="continuous">
    <origin rpy="0 0 0" xyz="-0.06221574501182705 0 0.02552966064449972"/>
    <axis xyz="-0.2684341436894733 -0.7071067811865476 -0.6541736088391974"/>
    <dynamics damping="0.0" friction="0.001"/>
    <parent link="back_right_wheel"/>
    <child link="back_right_roller_11"/>
  </joint>
  <gazebo reference="back_right_roller_11">
    <mu1 value="2000.0"/>
    <mu2 value="2000.0"/>
    <kp value="1000000.0"/>
    <kd value="100.0"/>
    <material>Gazebo/Black</material>
  </gazebo>
  <!--  link  -->
  <link name="back_right_roller_12">
    <collision>
      <geometry>
        <sphere radius="0.009"/>
      </geometry>
    </collision>
    <inertial>
      <mass value="0.036"/>
      <inertia ixx="3128e-9" ixy="0.0" ixz="0.0" iyy="3128e-9" iyz="0.0" izz="3128e-9"/>
    </inertial>
  </link>
  <joint name="back_right_roller_12_joint" type="continuous">
    <origin rpy="0 0 0" xyz="-0.06724956154854442 0 -0.00024284054137712588"/>
    <axis xyz="0.002553370907877698 -0.7071067811865476 -0.7071021710453214"/>
    <dynamics damping="0.0" friction="0.001"/>
    <parent link="back_right_wheel"/>
    <child link="back_right_roller_12"/>
  </joint>
  <gazebo reference="back_right_roller_12">
    <mu1 value="2000.0"/>
    <mu2 value="2000.0"/>
    <kp value="1000000.0"/>
    <kd value="100.0"/>
    <material>Gazebo/Black</material>
  </gazebo>
  <!--  link  -->
  <link name="back_right_roller_13">
    <collision>
      <geometry>
        <sphere radius="0.009"/>
      </geometry>
    </collision>
    <inertial>
      <mass value="0.036"/>
      <inertia ixx="3128e-9" ixy="0.0" ixz="0.0" iyy="3128e-9" iyz="0.0" izz="3128e-9"/>
    </inertial>
  </link>
  <joint name="back_right_roller_13_joint" type="continuous">
    <origin rpy="0 0 0" xyz="-0.062029747891165755 0 -0.025978315506560806"/>
    <axis xyz="0.2731515696430154 -0.7071067811865476 -0.6522179237046135"/>
    <dynamics damping="0.0" friction="0.001"/>
    <parent link="back_right_wheel"/>
    <child link="back_right_roller_13"/>
  </joint>
  <gazebo reference="back_right_roller_13">
    <mu1 value="2000.0"/>
    <mu2 value="2000.0"/>
    <kp value="1000000.0"/>
    <kd value="100.0"/>
    <material>Gazebo/Black</material>
  </gazebo>
  <!--  link  -->
  <link name="back_right_roller_14">
    <collision>
      <geometry>
        <sphere radius="0.009"/>
      </geometry>
    </collision>
    <inertial>
      <mass value="0.036"/>
      <inertia ixx="3128e-9" ixy="0.0" ixz="0.0" iyy="3128e-9" iyz="0.0" izz="3128e-9"/>
    </inertial>
  </link>
  <joint name="back_right_roller_14_joint" type="continuous">
    <origin rpy="0 0 0" xyz="-0.047352175978368535 0 -0.04775284211556018"/>
    <axis xyz="0.5021019848452515 -0.7071067811865476 -0.49788914108911725"/>
    <dynamics damping="0.0" friction="0.001"/>
    <parent link="back_right_wheel"/>
    <child link="back_right_roller_14"/>
  </joint>
  <gazebo reference="back_right_roller_14">
    <mu1 value="2000.0"/>
    <mu2 value="2000.0"/>
    <kp value="1000000.0"/>
    <kd value="100.0"/>
    <material>Gazebo/Black</material>
  </gazebo>
  <!--  link  -->
  <link name="back_right_roller_15">
    <collision>
      <geometry>
        <sphere radius="0.009"/>
      </geometry>
    </collision>
    <inertial>
      <mass value="0.036"/>
      <inertia ixx="3128e-9" ixy="0.0" ixz="0.0" iyy="3128e-9" iyz="0.0" izz="3128e-9"/>
    </inertial>
  </link>
  <joint name="back_right_roller_15_joint" type="continuous">
    <origin rpy="0 0 0" xyz="-0.025454754743320145 0 -0.06224642930287183"/>
    <axis xyz="0.6544962418544192 -0.7071067811865476 -0.2676465381775779"/>
    <dynamics damping="0.0" friction="0.001"/>
    <parent link="back_right_wheel"/>
    <child link="back_right_roller_15"/>
  </joint>
  <gazebo reference="back_right_roller_15">
    <mu1 value="2000.0"/>
    <mu2 value="2000.0"/>
    <kp value="1000000.0"/>
    <kd value="100.0"/>
    <material>Gazebo/Black</material>
  </gazebo>
  <transmission name="front_left_wheel_trans">
    <type>transmission_interface/SimpleTransmission</type>
    <actuator name="front_left_wheel_motor">
      <hardwareInterface>hardware_interface/EffortJointInterface</hardwareInterface>
      <mechanicalReduction>1</mechanicalReduction>
    </actuator>
    <joint name="front_left_wheel_joint">
      <hardwareInterface>hardware_interface/EffortJointInterface</hardwareInterface>
    </joint>
  </transmission>
  <transmission name="front_right_wheel_trans">
    <type>transmission_interface/SimpleTransmission</type>
    <actuator name="front_right_wheel_motor">
      <hardwareInterface>hardware_interface/EffortJointInterface</hardwareInterface>
      <mechanicalReduction>-1</mechanicalReduction>
    </actuator>
    <joint name="front_right_wheel_joint">
      <hardwareInterface>hardware_interface/EffortJointInterface</hardwareInterface>
    </joint>
  </transmission>
  <transmission name="back_left_wheel_trans">
    <type>transmission_interface/SimpleTransmission</type>
    <actuator name="back_left_wheel_motor">
      <hardwareInterface>hardware_interface/EffortJointInterface</hardwareInterface>
      <mechanicalReduction>1</mechanicalReduction>
    </actuator>
    <joint name="back_left_wheel_joint">
      <hardwareInterface>hardware_interface/EffortJointInterface</hardwareInterface>
    </joint>
  </transmission>
  <transmission name="back_right_wheel_trans">
    <type>transmission_interface/SimpleTransmission</type>
    <actuator name="back_right_wheel_motor">
      <hardwareInterface>hardware_interface/EffortJointInterface</hardwareInterface>
      <mechanicalReduction>-1</mechanicalReduction>
    </actuator>
    <joint name="back_right_wheel_joint">
      <hardwareInterface>hardware_interface/EffortJointInterface</hardwareInterface>
    </joint>
  </transmission>
  <!--  link  -->
  <link name="link1">
    <inertial>
      <mass value="1.7056"/>
      <origin xyz="0.004 0 0.0571"/>
      <inertia ixx="1.542e-2" ixy="0" ixz="-1.332e-3" iyy="1.028e-2" iyz="0" izz="1.017e-2"/>
    </inertial>
    <visual>
      <origin rpy="0 0 0" xyz="0 0 0"/>
      <geometry>
        <mesh filename="package://rm_description/meshes/engineer/link1.stl" scale="0.001 0.001 0.001"/>
      </geometry>
    </visual>
    <collision>
      <origin rpy="0 0 0" xyz="-0.045 0 0.035"/>
      <geometry>
        <box size="0.15 0.106 0.07"/>
      </geometry>
    </collision>
    <collision>
      <origin rpy="0 -0.95993 0" xyz="0.040 0 0.1"/>
      <geometry>
        <box size="0.17 0.106 0.095"/>
      </geometry>
    </collision>
    <collision>
      <origin rpy="1.5707963 0 0" xyz="0 0 0.05"/>
      <geometry>
        <cylinder length="0.188" radius="0.047"/>
      </geometry>
    </collision>
  </link>
  <link name="link2">
    <inertial>
      <mass value="1.4763"/>
      <origin xyz="0.05652 0 0"/>
      <inertia ixx="1.976e-3" ixy="5.791e-5" ixz="-2.47366e-7" iyy="8.418e-3" iyz="1.0e-7" izz="8.946e-3"/>
    </inertial>
    <visual>
      <origin rpy="0 0 0" xyz="0 0 0"/>
      <geometry>
        <mesh filename="package://rm_description/meshes/engineer/link2.stl" scale="0.001 0.001 0.001"/>
      </geometry>
    </visual>
    <collision>
      <origin xyz="0.062 0 0"/>
      <geometry>
        <box size="0.225 0.096 0.070"/>
      </geometry>
    </collision>
  </link>
  <link name="link3">
    <inertial>
      <mass value="0.5946"/>
      <origin xyz="0.0471 -0.0094 0.0003"/>
      <inertia ixx="6.49e-4" ixy="5.036e-5" ixz="-2.372e-5" iyy="2.739e-3" iyz="1.795e-6" izz="3.077e-3"/>
    </inertial>
    <visual>
      <origin rpy="0 0 0" xyz="0 0 0"/>
      <geometry>
        <mesh filename="package://rm_description/meshes/engineer/link3.stl" scale="0.001 0.001 0.001"/>
      </geometry>
    </visual>
    <collision>
      <origin xyz="0.063 0 0"/>
      <geometry>
        <box size="0.191 0.084 0.053"/>
      </geometry>
    </collision>
    <collision>
      <origin rpy="1.5707963 0 0" xyz="0 0 0"/>
      <geometry>
        <cylinder length="0.082" radius="0.047"/>
      </geometry>
    </collision>
  </link>
  <link name="link4">
    <inertial>
      <mass value="0.361"/>
      <origin xyz="0 0 0"/>
      <inertia ixx="2.593e-4" ixy="5.907e-3" ixz="2.629e-2" iyy="8.662e-5" iyz="0." izz="2.589e-4"/>
    </inertial>
    <visual>
      <origin rpy="0 0 0" xyz="0 0 0"/>
      <geometry>
        <mesh filename="package://rm_description/meshes/engineer/link4.stl" scale="0.001 0.001 0.001"/>
      </geometry>
    </visual>
    <collision>
      <origin rpy="0 0 0" xyz="0 0 0"/>
      <geometry>
        <box size="0.0513 0.074 0.0513"/>
      </geometry>
    </collision>
  </link>
  <link name="link5">
    <inertial>
      <mass value="0.249"/>
      <origin xyz="0.02737 0.0 0.0"/>
      <inertia ixx="6.090e-5" ixy="7.70024e-7" ixz="7.35489e-7" iyy="2.293e-4" iyz="0." izz="2.293e-4"/>
    </inertial>
    <visual>
      <origin rpy="0 0 0" xyz="0 0 0"/>
      <geometry>
        <mesh filename="package://rm_description/meshes/engineer/link5.stl" scale="0.001 0.001 0.001"/>
      </geometry>
    </visual>
    <collision>
      <origin rpy="0 0 0" xyz="0.015 0 0"/>
      <geometry>
        <box size="0.056 0.0513 0.0513"/>
      </geometry>
    </collision>
  </link>
  <!--  joint  -->
  <joint name="joint1" type="revolute">
    <axis xyz="0 0 1"/>
    <origin xyz="0.133 0 0.1"/>
    <!--      limit not work while type="continuous"-->
    <limit effort="20" lower="-3.141592653589793" upper="3.141592653589793" velocity="25"/>
    <dynamics damping="0.0" friction="0.1"/>
    <parent link="base_link"/>
    <child link="link1"/>
  </joint>
  <joint name="joint2" type="revolute">
    <axis xyz="0 1 0"/>
    <origin xyz="0.05909 0 0.1280"/>
    <limit effort="30" lower="-2.231" upper="0.407" velocity="10"/>
    <dynamics damping="0.0" friction="0.8"/>
    <parent link="link1"/>
    <child link="link2"/>
  </joint>
  <joint name="joint3" type="revolute">
    <axis xyz="0 1 0"/>
    <origin xyz="0.16 0 0"/>
    <limit effort="30" lower="-2.1645" upper="2.4078" velocity="10"/>
    <dynamics damping="0.0" friction="0.5"/>
    <parent link="link2"/>
    <child link="link3"/>
  </joint>
  <joint name="joint4" type="revolute">
    <axis xyz="0 1 0"/>
    <origin xyz="0.145 0 0"/>
    <limit effort="2.4" lower="-1.7278759594743864" upper="1.7278759594743864" velocity="34"/>
    <dynamics damping="0.0" friction="0.05"/>
    <parent link="link3"/>
    <child link="link4"/>
  </joint>
  <joint name="joint5" type="revolute">
    <axis xyz="1 0 0"/>
    <origin xyz="0 0 0"/>
    <limit effort="1.2" lower="-3.141592653589793" upper="3.141592653589793" velocity="34"/>
    <dynamics damping="0.0" friction="0.05"/>
    <parent link="link4"/>
    <child link="link5"/>
  </joint>
  <!-- transmission -->
  <transmission name="trans_joint1">
    <type>transmission_interface/SimpleTransmission</type>
    <actuator name="joint1_motor">
      <mechanicalReduction>4</mechanicalReduction>
    </actuator>
    <joint name="joint1">
      <hardwareInterface>hardware_interface/EffortJointInterface</hardwareInterface>
      <offset>-0.02552</offset>
    </joint>
  </transmission>
  <transmission name="trans_joint3">
    <type>transmission_interface/SimpleTransmission</type>
    <actuator name="joint3_motor">
      <mechanicalReduction>3</mechanicalReduction>
    </actuator>
    <joint name="joint3">
      <hardwareInterface>hardware_interface/EffortJointInterface</hardwareInterface>
      <offset>-0.6104</offset>
    </joint>
  </transmission>
  <transmission name="trans_joint2">
    <type>transmission_interface/SimpleTransmission</type>
    <actuator name="joint2_motor">
      <mechanicalReduction>-3</mechanicalReduction>
    </actuator>
    <joint name="joint2">
      <hardwareInterface>hardware_interface/EffortJointInterface</hardwareInterface>
      <offset>0</offset>
    </joint>
  </transmission>
  <transmission name="trans_joint4">
    <type>transmission_interface/SimpleTransmission</type>
    <actuator name="joint4_motor">
      <hardwareInterface>hardware_interface/EffortJointInterface</hardwareInterface>
      <mechanicalReduction>1</mechanicalReduction>
    </actuator>
    <joint name="joint4">
      <hardwareInterface>hardware_interface/EffortJointInterface</hardwareInterface>
    </joint>
  </transmission>
  <transmission name="trans_joint5">
    <type>transmission_interface/SimpleTransmission</type>
    <actuator name="joint5_motor">
      <hardwareInterface>hardware_interface/EffortJointInterface</hardwareInterface>
      <mechanicalReduction>1</mechanicalReduction>
    </actuator>
    <joint name="joint5">
      <hardwareInterface>hardware_interface/EffortJointInterface</hardwareInterface>
    </joint>
  </transmission>
  <material name="Black">
    <color rgba="0 0 0 1"/>
  </material>
  <material name="White">
    <color rgba="1 1 1 1"/>
  </material>
  <link name="palm">
    <inertial>
      <origin rpy="0 0 0" xyz="0.01877 0.0475 -0.000028"/>
      <mass value="0.406611"/>
      <inertia ixx="2.719e-3" ixy="-3.243e-4" ixz="228.248e-9" iyy="2.564e-4" iyz="1515.727e-9" izz="2.9e-3"/>
    </inertial>
    <visual>
      <geometry>
        <mesh filename="package://rm_description/meshes/engineer/palm.stl" scale="0.001 0.001 0.001"/>
      </geometry>
    </visual>
    <collision>
      <origin rpy="0 0 0" xyz="0.0225 0.0 0"/>
      <geometry>
        <box size="0.045 0.2658 0.0675"/>
      </geometry>
    </collision>
  </link>
  <link name="right_finger">
    <inertial>
      <origin rpy="0 0 0" xyz="0.01491 -0.06058 0"/>
      <mass value="0.203967"/>
      <inertia ixx="1.025e-3" ixy="3.865e-4" ixz="-1.144e-9" iyy="3.051e-4" iyz="4.649e-9" izz="1.295e-3"/>
    </inertial>
    <visual>
      <geometry>
        <mesh filename="package://rm_description/meshes/engineer/right_finger.stl" scale="0.001 0.001 0.001"/>
      </geometry>
    </visual>
    <collision>
      <origin rpy="0 0 0" xyz="0.011 -0.04 0"/>
      <geometry>
        <box size="0.048 0.026 0.030"/>
      </geometry>
    </collision>
    <collision>
      <origin rpy="0 0 0" xyz="0.0235 -0.0832 0"/>
      <geometry>
        <box size="0.022 0.1123 0.03"/>
      </geometry>
    </collision>
    <collision>
      <origin rpy="0 0 0" xyz="0.069 -0.13 0"/>
      <geometry>
        <box size="0.112 0.0157 0.03"/>
      </geometry>
    </collision>
    <collision>
      <origin rpy="0 0 0" xyz="0.105 -0.1232 0"/>
      <geometry>
        <box size="0.04 0.0323 0.03"/>
      </geometry>
    </collision>
  </link>
  <link name="left_finger">
    <inertial>
      <origin rpy="0 0 0" xyz="0.01491 0.061581 0"/>
      <mass value="0.203967"/>
      <inertia ixx="1.053e-3" ixy="-3.865e-4" ixz="-1.144e-9" iyy="3.051e-4" iyz="-4.733e-9" izz="1.323e-3"/>
    </inertial>
    <visual>
      <geometry>
        <mesh filename="package://rm_description/meshes/engineer/left_finger.stl" scale="0.001 0.001 0.001"/>
      </geometry>
    </visual>
    <collision>
      <origin rpy="0 0 0" xyz="0.011 0.04 0"/>
      <geometry>
        <box size="0.048 0.026 0.030"/>
      </geometry>
    </collision>
    <collision>
      <origin rpy="0 0 0" xyz="0.0235 0.0832 0"/>
      <geometry>
        <box size="0.022 0.1123 0.03"/>
      </geometry>
    </collision>
    <collision>
      <origin rpy="0 0 0" xyz="0.069 0.12 0"/>
      <geometry>
        <box size="0.112 0.03 0.03"/>
      </geometry>
    </collision>
  </link>
  <link name="camera">
    <inertial>
      <mass value="0.05"/>
      <origin xyz="0 0 0"/>
      <inertia ixx="1.271e-3" ixy="2.07e-7" ixz="8.854e-6" iyy="5.190e-4" iyz="1.001e-6" izz="9.976e-4"/>
    </inertial>
    <visual>
      <origin rpy="0 0 0" xyz=" 0 0 0 "/>
      <geometry>
        <box size="0.022 0.021 0.0226"/>
      </geometry>
      <material name="Black"/>
    </visual>
    <collision>
      <origin rpy="0 0 0" xyz="0.0 0.0 0.0"/>
      <geometry>
        <box size="0.01 0.04 0.04"/>
      </geometry>
    </collision>
  </link>
  <joint name="camera_joint" type="fixed">
    <parent link="palm"/>
    <child link="camera"/>
    <origin rpy="0 0 0" xyz="0.055 -0.085 0.0962"/>
    <axis xyz="0 0 1"/>
  </joint>
  <joint name="palm_joint" type="fixed">
    <parent link="link5"/>
    <child link="palm"/>
    <origin rpy="0 0 0" xyz="0.039 0 0"/>
  </joint>
  <joint name="right_finger_joint" type="prismatic">
    <parent link="palm"/>
    <child link="right_finger"/>
    <origin rpy="0 0 0" xyz="0.032 0 0"/>
    <axis xyz="0 1 0"/>
    <limit effort="588" lower="0.0" upper="0.02" velocity="3.772"/>
  </joint>
  <joint name="left_finger_joint" type="prismatic">
    <parent link="palm"/>
    <child link="left_finger"/>
    <origin rpy="0 0 0" xyz="0.032 0 0"/>
    <axis xyz="0 -1 0"/>
    <limit effort="588" lower="0.0" upper="0.02" velocity="3.772"/>
    <mimic joint="right_finger_joint"/>
  </joint>
  <gazebo>
    <plugin filename="libroboticsgroup_upatras_gazebo_mimic_joint_plugin.so" name="left_finger_mimic_joint_plugin">
      <joint>right_finger_joint</joint>
      <mimicJoint>left_finger_joint</mimicJoint>
      <hasPID/>
      <maxEffort>588.0</maxEffort>
    </plugin>
  </gazebo>
  <gazebo reference="right_finger">
    <self_collide>1</self_collide>
    <mu1 value="2000000000.0"/>
    <mu2 value="2000000000.0"/>
    <kp value="1000000.0"/>
    <kd value="100.0"/>
    <material>Gazebo/Black</material>
  </gazebo>
  <gazebo reference="left_finger">
    <self_collide>1</self_collide>
    <mu1 value="2000000000.0"/>
    <mu2 value="2000000000.0"/>
    <kp value="1000000.0"/>
    <kd value="100.0"/>
    <material>Gazebo/Black</material>
  </gazebo>
  <transmission name="trans_right_finger_joint">
    <type>transmission_interface/SimpleTransmission</type>
    <joint name="right_finger_joint">
      <hardwareInterface>hardware_interface/EffortJointInterface</hardwareInterface>
      <offset>0.0</offset>
    </joint>
    <actuator name="right_finger_motor">
      <hardwareInterface>hardware_interface/EffortJointInterface</hardwareInterface>
      <mechanicalReduction>-4712.388</mechanicalReduction>
    </actuator>
  </transmission>
  <gazebo>
    <plugin filename="librm_robot_hw_sim.so" name="rm_ros_control">
      <robotNamespace>/</robotNamespace>
      <robotSimType>rm_gazebo/RmRobotHWSim</robotSimType>
    </plugin>
  </gazebo>
</robot>
