<robot xmlns:xacro="http://www.ros.org/wiki/xacro">

  <xacro:include filename="$(find rm_description)/urdf/common/friction.urdf.xacro"/>


  <xacro:property name="wheel_offset_x" value="0.0504"/>
  <xacro:property name="wheel_offset_y" value="0.0365"/>
  <xacro:property name="wheel_offset_z" value="0.01072"/>


  <xacro:friction_wheel prefixs="lower_left" connected_to="lower_pitch"
                        wheel_x_offset="${wheel_offset_x}" wheel_y_offset="${-wheel_offset_y}"
                        wheel_z_offset="${wheel_offset_z}"/>

  <xacro:friction_wheel prefixs="lower_right" connected_to="lower_pitch"
                        wheel_x_offset="${wheel_offset_x}" wheel_y_offset="${wheel_offset_y}"
                        wheel_z_offset="${wheel_offset_z}"/>


  <link name="lower_trigger">
    <inertial>
      <mass value="0.25496"/>
      <origin xyz="0.282e-3 0.011e-3 18.873e-3"/>
      <inertia ixx="2.844e-4" ixy="-432.025e-9" ixz="-882.662e-9" iyy="2.858e-4"
               iyz="-19.177e-9" izz="2.347e-4"/>
    </inertial>
    <visual>
      <origin xyz="0 0 0" rpy="0 0 0"/>
      <geometry>
        <mesh filename="package://rm_description/meshes/sentry/lower_trigger.stl" scale="0.001 0.001 0.001"/>
      </geometry>
    </visual>
    <collision>
      <origin xyz="0 0 0" rpy="0 0 0"/>
      <geometry>
        <mesh filename="package://rm_description/meshes/sentry/lower_trigger.stl" scale="0.001 0.001 0.001"/>
      </geometry>
    </collision>
  </link>

  <joint name="lower_trigger_joint" type="continuous">
    <origin xyz="0 0.15 -0.136" rpy="0 0 0"/>
    <dynamics damping="0.0" friction="0.01"/>
    <limit effort="1.0" velocity="43.54" lower="-1e16" upper="1e16"/>
    <parent link="lower_pitch"/>
    <child link="lower_trigger"/>
    <axis xyz="0 0 1 "/>
  </joint>


</robot>
