<robot xmlns:xacro="http://www.ros.org/wiki/xacro">

    <xacro:include filename="$(find rm_description)/urdf/common/friction.urdf.xacro"/>


    <xacro:property name="wheel_offset_x" value="0.009"/>
    <xacro:property name="wheel_offset_y" value="0.0365"/>
    <xacro:property name="wheel_offset_z" value="0.00576"/>


    <xacro:friction_wheel prefixs="upper_left" connected_to="upper_pitch"
                          wheel_x_offset="${wheel_offset_x}" wheel_y_offset="${-wheel_offset_y}"
                          wheel_z_offset="${wheel_offset_z}"/>

    <xacro:friction_wheel prefixs="upper_right" connected_to="upper_pitch"
                          wheel_x_offset="${wheel_offset_x}" wheel_y_offset="${wheel_offset_y}"
                          wheel_z_offset="${wheel_offset_z}"/>


    <link name="upper_trigger">
        <inertial>
            <mass value="0.328"/>
            <origin xyz="1.854e-3 -4.952e-3 20.252e-3"/>
            <inertia ixx="5.284e-4" ixy="26474.311e-9" ixz="-5533.967e-9" iyy="3.633e-4"
                     iyz="3258.006e-9" izz="4.750e-4"/>
        </inertial>
        <visual>
            <origin xyz="0 0 0" rpy="0 0 0"/>
            <geometry>
                <mesh filename="package://rm_description/meshes/sentry/upper_trigger.stl" scale="0.001 0.001 0.001"/>
            </geometry>
        </visual>
        <collision>
            <origin xyz="0 0 0" rpy="0 0 0"/>
            <geometry>
                <mesh filename="package://rm_description/meshes/sentry/upper_trigger.stl" scale="0.001 0.001 0.001"/>
            </geometry>
        </collision>
    </link>

    <joint name="upper_trigger_joint" type="continuous">
        <origin xyz="-64.86e-3 0 -19e-3" rpy="0 0 0"/>
        <dynamics damping="0.0" friction="0.01"/>
        <limit effort="1.0" velocity="43.54" lower="-1e16" upper="1e16"/>
        <parent link="upper_pitch"/>
        <child link="upper_trigger"/>
        <axis xyz="0 0 1 "/>
    </joint>


</robot>
