<?xml version="1.0" encoding="utf-8"?>
<robot xmlns:xacro="http://www.ros.org/wiki/xacro">

    <xacro:property name="threshold" value="0.03"/>
    <xacro:property name="yaw_lower_limit" value="-2.90"/>
    <xacro:property name="yaw_upper_limit" value="2.97"/>
    <xacro:property name="pitch_lower_limit" value="-0.843"/>
    <xacro:property name="pitch_upper_limit" value="0.472"/>

    <link name="upper_yaw">
        <visual>
            <geometry>
                <mesh filename="package://rm_description/meshes/sentry/upper_yaw.stl"
                      scale="0.001 0.001 0.001"/>
            </geometry>
        </visual>
        <inertial>
            <mass value="934.339e-3"/>
            <origin xyz="-0.08e-3 -61.185e-3 90.777e-3" rpy="0 0 0"/>
            <inertia ixx="1.880e-2" ixy="-6662.219e-9" ixz="7064.827e-9" iyy="1.083e-2"
                     iyz="7.150e-3" izz="9.057e-3"/>
        </inertial>
        <collision>
            <origin xyz="0 0 0" rpy="0 0 0"/>
            <geometry>
                <mesh filename="package://rm_description/meshes/sentry/upper_yaw.stl"
                      scale="0.001 0.001 0.001"/>
            </geometry>
        </collision>
    </link>

    <joint name="upper_yaw_joint" type="revolute">
        <parent link="base_link"/>
        <child link="upper_yaw"/>
        <axis xyz="0 0 1"/>
        <origin xyz="0 0 83.4e-3"/>
        <dynamics damping="0" friction="0.1"/>
        <limit effort="1.2" velocity="13.82" lower="${yaw_lower_limit}" upper="${yaw_upper_limit}"/>
        <safety_controller k_position="100" k_velocity="0.1"
                           soft_lower_limit="${yaw_lower_limit+threshold}"
                           soft_upper_limit="${yaw_upper_limit-threshold}"/>
    </joint>

    <link name="upper_pitch">
        <inertial>
            <mass value="1227.797e-3"/>
            <origin xyz="15.667e-3 -0.268e-3 27.267e-3"/>
            <inertia ixx="4.484e-3" ixy="813.964e-9" ixz="2.786e-4" iyy="6.599e-3"
                     iyz="-6822.846e-9" izz="5.343E-3"/>
        </inertial>
        <visual>
            <origin xyz="0 0 0" rpy="0 0 0"/>
            <geometry>
                <mesh filename="package://rm_description/meshes/sentry/upper_pitch.stl" scale="0.001 0.001 0.001"/>
            </geometry>
        </visual>
        <collision>
            <origin xyz="0 0 0" rpy="0 0 0"/>
            <geometry>
                <mesh filename="package://rm_description/meshes/sentry/upper_pitch.stl" scale="0.001 0.001 0.001"/>
            </geometry>
        </collision>
    </link>

    <joint name="upper_pitch_joint" type="revolute">
        <parent link="upper_yaw"/>
        <child link="upper_pitch"/>
        <axis xyz="0 1 0"/>
        <origin xyz="0 0 0.125"/>
        <dynamics damping="0" friction="0.1"/>
        <limit effort="1.2" velocity="13.82" lower="${pitch_lower_limit}" upper="${pitch_upper_limit}"/>
        <safety_controller k_position="100" k_velocity="0.1"
                           soft_lower_limit="${pitch_lower_limit+threshold}"
                           soft_upper_limit="${pitch_upper_limit-threshold}"/>
    </joint>

    <!--  <link name="upper_camera">-->
    <!--    <inertial>-->
    <!--          <mass value="0.17671"/>-->
    <!--          <origin xyz="0.022 0.0 0.0"/>-->
    <!--          <inertia ixx="2.129e-5" ixy="7.329e-8" ixz="-1.11e-7" iyy="2.198e-4" iyz="-8.04e-7" izz="2.197e-4"/>-->
    <!--        </inertial>-->
    <!--        <visual>-->
    <!--          <origin xyz=" 0 0 0 " rpy="0 -1.57 0"/>-->
    <!--          <geometry>-->
    <!--            <mesh filename="package://rm_description/meshes/common/camera.stl" scale="0.001 0.001 0.001"/>-->
    <!--          </geometry>-->
    <!--          <material name="Black"/>-->
    <!--        </visual>-->
    <!--        <collision>-->
    <!--          <origin xyz="0 0 0" rpy="0 -1.57 0"/>-->
    <!--          <geometry>-->
    <!--            <mesh filename="package://rm_description/meshes/common/camera.stl" scale="0.001 0.001 0.001"/>-->
    <!--          </geometry>-->
    <!--        </collision>-->
    <!--      </link>-->

    <!--      <joint name="camera_joint" type="fixed">-->
    <!--        <parent link="pitch"/>-->
    <!--        <child link="camera"/>-->
    <!--        <origin xyz="0.086  0.0 -0.040" rpy="-1.57 0 -1.57"/>-->
    <!--        <axis xyz="0 0 1"/>-->
    <!--      </joint>-->

</robot>
