<robot xmlns:xacro="http://www.ros.org/wiki/xacro">

  <xacro:property name="wheel_radius" value="0.07625"/>
  <xacro:property name="M_PI" value="3.14159265359"/>

  <xacro:macro name="mecanum_wheel" params="prefix reflect">
    <link name="${prefix}_wheel">
      <visual>
        <geometry>
          <mesh filename="package://rm_description/meshes/common/mecanum_wheel.stl"/>
          <xacro:if value="${reflect == -1}">
            <origin rpy="0 0 ${M_PI}"/>
          </xacro:if>
        </geometry>
      </visual>
    </link>
    <link name="${prefix}_rotor">
      <collision>
        <geometry>
          <sphere radius="${wheel_radius}"/>
        </geometry>
      </collision>
    </link>
    <joint name="${prefix}_rotor_joint" type="continuous">
      <axis xyz="${reflect * 0.70719678} ${reflect * 0.70719678} 0"/>
      <parent link="${prefix}_wheel"/>
      <child link="${prefix}_rotor"/>
    </joint>
  </xacro:macro>


  <!--  <xacro:mecanum_wheel prefix="test" reflect="1"/>-->
  <link name="wheel">
    <visual>
      <geometry>
        <mesh filename="package://rm_description/meshes/common/mecanum_wheel.stl"/>
      </geometry>
    </visual>
    <collision>
      <geometry>
        <sphere radius="${wheel_radius}"/>
      </geometry>
    </collision>
  </link>

  <!--  <xacro:mecanum_wheel prefix="test" reflect="1"/>-->

  <!-- Gazebo plugin for ROS Control -->
  <gazebo>
    <plugin name="gazebo_ros_control" filename="libgazebo_ros_control.so">
      <robotNamespace>/</robotNamespace>
    </plugin>
  </gazebo>

</robot>