<robot xmlns:xacro="http://www.ros.org/wiki/xacro">

  <xacro:property name="wheel_radius" value="0.07625"/>
  <xacro:macro name="mecanum_wheel" params="prefix parent wheel_x_offset wheel_y_offset wheel_z_offset reflect">
    <!--  link  -->
    <link name="${prefix}_wheel">
      <visual>
        <geometry>
          <xacro:if value="${reflect == 1}">
            <mesh filename="package://rm_description/meshes/common/left_threaded_mecanum_wheel.stl"
                  scale="0.035 0.035 0.035"/>
          </xacro:if>
          <xacro:if value="${reflect == -1}">
            <mesh filename="package://rm_description/meshes/common/right_threaded_mecanum_wheel.stl"
                  scale="0.035 0.035 0.035"/>
          </xacro:if>
        </geometry>
      </visual>
      <inertial>
        <mass value="0.59"/>
        <inertia ixx="1.416e-3" ixy="0.0" ixz="0.0" iyy="2.749e-3" iyz="0.0" izz="1.416e-3"/>
      </inertial>
    </link>
    <link name="${prefix}_rotor">
      <collision>
        <geometry>
          <sphere radius="${wheel_radius}"/>
        </geometry>
      </collision>
      <inertial>
        <mass value="0.036"/>
        <inertia ixx="3128e-9" ixy="-1638.12e-9" ixz="0.0" iyy="3128e-9" iyz="0.0" izz="4766e-9"/>
      </inertial>
      <gazebo>
        <mu1>200</mu1>
        <mu2>200</mu2>
      </gazebo>
    </link>

    <!--  joint  -->
    <joint name="${prefix}_wheel_joint" type="continuous">
      <axis xyz="0 1 0"/>
      <origin xyz="${wheel_x_offset} ${wheel_y_offset} ${wheel_offset_z}" rpy="0 0 0"/>
      <dynamics damping="0.1" friction="0.1"/>
      <parent link="${parent}"/>
      <child link="${prefix}_wheel"/>
    </joint>
    <joint name="${prefix}_rotor_joint" type="continuous">
      <axis xyz="${0.70719678} ${reflect * 0.70719678} 0"/>
      <parent link="${prefix}_wheel"/>
      <child link="${prefix}_rotor"/>
    </joint>
    <!-- transmission -->
    <transmission name="${prefix}_wheel_trans">
      <type>transmission_interface/SimpleTransmission</type>
      <actuator name="${prefix}_wheel_actuator">
        <hardwareInterface>hardware_interface/EffortJointInterface</hardwareInterface>
        <mechanicalReduction>${reflect}</mechanicalReduction>
      </actuator>
      <joint name="${prefix}_wheel_joint">
        <hardwareInterface>hardware_interface/EffortJointInterface</hardwareInterface>
      </joint>
    </transmission>

  </xacro:macro>

</robot>