<robot xmlns:xacro="http://www.ros.org/wiki/xacro">

    <xacro:property name="wheel_radius" value="0.07625"/>
    <xacro:property name="wheel_joint_effort" value="5"/>
    <xacro:property name="wheel_joint_velocity" value="50"/>

    <xacro:macro name="rubber_wheel"
                 params="prefix connected_to wheel_x_offset wheel_y_offset wheel_z_offset">
        <!--  link  -->
        <link name="${prefix}_wheel">
            <visual>
                <geometry>
                    <mesh filename="package://rm_description/meshes/common/rubber_wheel.stl"
                          scale="0.001 0.001 0.001"/>
                </geometry>
            </visual>
            <inertial>
                <mass value="0.23"/>
                <inertia ixx="5.647e+2" ixy="0.0" ixz="0.0" iyy="3.048e+2" iyz="0.0" izz="3.048e+2"/>
            </inertial>
        </link>

        <!--  joint  -->
        <joint name="${prefix}_wheel_joint" type="revolute">
            <axis xyz="0 1 0"/>
            <origin xyz="${wheel_x_offset} ${wheel_y_offset} ${wheel_offset_z}" rpy="0 0 0"/>
            <!--      limit not work while type="continuous"-->
            <limit effort="${wheel_joint_effort}" velocity="${wheel_joint_velocity}" lower="-1e16" upper="1e16"/>
            <dynamics damping="0.0" friction="0.05"/>
            <parent link="${connected_to}"/>
            <child link="${prefix}_wheel"/>
        </joint>

        <!-- transmission -->
        <transmission name="${prefix}_wheel_trans">
            <type>transmission_interface/SimpleTransmission</type>
            <actuator name="${prefix}_wheel_actuator">
                <hardwareInterface>hardware_interface/EffortJointInterface</hardwareInterface>
                <mechanicalReduction>1</mechanicalReduction>
            </actuator>
            <joint name="${prefix}_wheel_joint">
                <hardwareInterface>hardware_interface/EffortJointInterface</hardwareInterface>
            </joint>
        </transmission>

    </xacro:macro>

</robot>