<robot xmlns:xacro="http://www.ros.org/wiki/xacro">

    <xacro:macro name="swerve_drive" params="prefix wheel_x_offset wheel_y_offset wheel_z_offset  connected_to">

        <link name="${prefix}_pivot">
            <visual>
                <origin xyz="0 0 0" rpy="0 0 0"/>
                <geometry>
                    <mesh filename="package://rm_description/meshes/common/swerve_pivot.stl"
                          scale="0.001 0.001 0.001"/>
                </geometry>
            </visual>
            <inertial>
                <mass value="2.819"/>
                <origin xyz="0. 0.0 0.004" rpy="0 0 0"/>
                <inertia ixx="3.904e-3" ixy="3.689e-6" ixz="-9.096e-6" iyy="3.847e-3" iyz="-9.129e-5" izz="1.952e-3"/>
            </inertial>
            <collision>
                <origin xyz="0 0 0" rpy="0 0 0"/>
                <geometry>
                    <mesh filename="package://rm_description/meshes/common/swerve_pivot.stl"
                          scale="0.001 0.001 0.001"/>
                </geometry>
            </collision>
        </link>

        <joint name="${prefix}_pivot_joint" type="continuous">
            <axis xyz="0 0 1"/>
            <origin xyz="${wheel_x_offset} ${wheel_y_offset} ${wheel_z_offset}" rpy="0 0 0"/>
            <parent link="${connected_to}"/>
            <child link="${prefix}_pivot"/>
        </joint>


        <link name="${prefix}_wheel">
            <visual>
                <origin xyz="0 0 0" rpy="0 0 0"/>
                <geometry>
                    <mesh filename="package://rm_description/meshes/common/swerve_wheel.stl"
                          scale="0.001 0.001 0.001"/>
                </geometry>
            </visual>
            <inertial>
                <mass value="0.213"/>
                <origin xyz="0 -0.007 0.0" rpy="0 0 0"/>
                <inertia ixx="2.012e-4" ixy="0" ixz="0" iyy="2.618e-4" iyz="8.07e-7" izz="2.002e-4"/>
            </inertial>
            <collision>
                <origin xyz="0 0 0" rpy="0 0 0"/>
                <geometry>
                    <mesh filename="package://rm_description/meshes/common/swerve_wheel.stl"
                          scale="0.001 0.001 0.001"/>
                </geometry>
            </collision>
        </link>

        <joint name="${prefix}_wheel_joint" type="continuous">
            <axis xyz="0 1 0"/>
            <origin xyz="0 -0.001 -0.094" rpy="0 0 0"/>
            <parent link="${prefix}_pivot"/>
            <child link="${prefix}_wheel"/>
        </joint>

    </xacro:macro>

</robot>