<robot xmlns:xacro="http://www.ros.org/wiki/xacro">

    <xacro:macro name="friction_wheel"
                 params="prefixs:='' connected_to:=''  wheel_x_offset:='0' wheel_y_offset:='0' wheel_z_offset:='0' ">

        <link name="${prefixs}_friction_wheel">
            <inertial>
                <mass value="0.017875"/>
                <origin xyz="-3.118e-12 0 0"/>
                <inertia ixx="3693.92e-9" ixy="0" ixz="0" iyy="3693.921e-9"
                         iyz="0" izz="7107.532e-9"/>
            </inertial>
            <visual>
                <origin xyz="0 0 0" rpy="0 0 0"/>
                <geometry>
                    <mesh filename="package://rm_description/meshes/rmua/friction.stl" scale="0.001 0.001 0.001"/>
                </geometry>
            </visual>
            <collision>
                <origin xyz="0 0 0" rpy="0 0 0"/>
                <geometry>
                    <mesh filename="package://rm_description/meshes/rmua/friction.stl" scale="0.001 0.001 0.001"/>
                </geometry>
            </collision>
        </link>

        <joint name="${prefixs}_friction_wheel_joint" type="continuous">
            <origin xyz="${wheel_x_offset} ${wheel_y_offset} ${wheel_offset_z}" rpy="0 0 0"/>"
            <dynamics damping="0.0" friction="0.01"/>
            <limit upper="1e16" lower="-1e16" effort="0.156" velocity="942.66"/>
            <parent link="${connected_to}"/>
            <child link="${prefixs}_friction_wheel"/>
            <axis xyz="0 0 1"/>

        </joint>

    </xacro:macro>
</robot>
