<?xml version="1.0" encoding="utf-8"?>
<robot xmlns:xacro="http://www.ros.org/wiki/xacro">

    <xacro:property name="threshold" value="0.1"/>
    <xacro:property name="pitch_lower_limit" value="-0.482"/>
    <xacro:property name="pitch_upper_limit" value="0.394"/>
    <xacro:property name="yaw_lower_limit" value="-1.732"/>
    <xacro:property name="yaw_upper_limit" value="1.674"/>

    <link name="yaw">
        <inertial>
            <mass value="1.021711"/>
            <origin xyz="-30.514e-3 -2.798e-3 96.993e-3"/>
            <inertia ixx="1.528e-2" ixy="-2.098e-4" ixz="3.078e-3" iyy="1.616e-2"
                     iyz="1.428e-4" izz="5.606e-3"/>
        </inertial>
        <visual>
            <origin xyz="0 0 0" rpy="0 0 0"/>
            <geometry>
                <mesh filename="package://rm_description/meshes/rmua/yaw.stl" scale="0.001 0.001 0.001"/>
            </geometry>
        </visual>
        <collision>
            <origin xyz="0 0 0" rpy="0 0 0"/>
            <geometry>
                <mesh filename="package://rm_description/meshes/rmua/yaw.stl" scale="0.001 0.001 0.001"/>
            </geometry>
        </collision>
    </link>

    <joint name="yaw_joint" type="revolute">
        <origin xyz="0 0 89.5e-3"
                rpy="0 0 0"/>
        <dynamics damping="0.0" friction="0.1"/>
        <limit effort="1.2" velocity="31" lower="${yaw_lower_limit}" upper="${yaw_upper_limit}"/>
        <safety_controller k_position="100" k_velocity="0.1"
                           soft_lower_limit="${yaw_lower_limit+threshold}"
                           soft_upper_limit="${yaw_upper_limit-threshold}"/>
        <parent link="base_link"/>
        <child link="yaw"/>
        <axis xyz="0 0 1"/>
    </joint>

    <link name="pitch">
        <inertial>
            <mass value="0.786302"/>
            <origin xyz="0.057725 -0.041817 0.025191"/>
            <inertia ixx="5e-3" ixy="3.275e-3" ixz="-3.397e-4" iyy="7.794e-3"
                     iyz="6.769e-4" izz="9.897e-3"/>
        </inertial>
        <visual>
            <origin xyz="0 0 0" rpy="0 0 0"/>
            <geometry>
                <mesh filename="package://rm_description/meshes/rmua/pitch.stl" scale="0.001 0.001 0.001"/>
            </geometry>
        </visual>
        <collision>
            <origin xyz="0 0 0" rpy="0 0 0"/>
            <geometry>
                <mesh filename="package://rm_description/meshes/rmua/pitch.stl" scale="0.001 0.001 0.001"/>
            </geometry>
        </collision>
    </link>

    <joint name="pitch_joint" type="revolute">
        <origin xyz="0.327e-3 71e-3 216.5e-3" rpy="0 0 0"/>
        <dynamics damping="0.0" friction="0.1"/>
        <limit effort="1.2" velocity="13.82" lower="${pitch_lower_limit}" upper="${pitch_upper_limit}"/>
        <safety_controller k_position="100" k_velocity="0.1"
                           soft_lower_limit="${pitch_lower_limit+threshold}"
                           soft_upper_limit="${pitch_upper_limit-threshold}"/>
        <parent link="yaw"/>
        <child link="pitch"/>
        <axis xyz="0 1 0 "/>
    </joint>

</robot>
