<robot xmlns:xacro="http://www.ros.org/wiki/xacro">

    <xacro:include filename="$(find rm_description)/urdf/common/friction.urdf.xacro"/>


    <xacro:property name="wheel_offset_x" value="0.075"/>
    <xacro:property name="wheel_offset_y" value="0.049"/>
    <xacro:property name="wheel_offset_z" value="0"/>


    <xacro:friction_wheel prefixs="left" connected_to="pitch"
                          wheel_x_offset="${wheel_offset_x}" wheel_y_offset="${wheel_offset_y}"
                          wheel_z_offset="${wheel_offset_z}"/>

    <xacro:friction_wheel prefixs="right" connected_to="pitch"
                          wheel_x_offset="${wheel_offset_x}" wheel_y_offset="${-wheel_offset_y}"
                          wheel_z_offset="${wheel_offset_z}"/>


    <link name="trigger">
        <inertial>
            <mass value="1.4"/>
            <origin xyz="-0.0146 -0.00736 -0.00154"/>
            <inertia ixx="4.443e-3" ixy="-1.694e-3" ixz="-1.776e-3" iyy="1.122e-2"
                     iyz="-3.693e-4" izz="1.347e-2"/>
        </inertial>
        <visual>
            <origin xyz="0 0 0" rpy="0 0 0"/>
            <geometry>
                <mesh filename="package://rm_description/meshes/hero/trigger.stl" scale="0.001 0.001 0.001"/>
            </geometry>
        </visual>
        <collision>
            <origin xyz="0 0 0" rpy="0 0 0"/>
            <geometry>
                <mesh filename="package://rm_description/meshes/hero/trigger.stl" scale="0.001 0.001 0.001"/>
            </geometry>
        </collision>
    </link>

    <joint name="trigger_joint" type="continuous">
        <origin xyz="0 0 0.063" rpy="0 0 0"/>
        <dynamics damping="0.0" friction="0.01"/>
        <limit effort="6.99" velocity="35.758" lower="-1e16" upper="1e16"/>
        <parent link="base_link"/>
        <child link="trigger"/>
        <axis xyz="0 0 1 "/>

    </joint>

</robot>
