<?xml version="1.0" encoding="utf-8"?>
<robot xmlns:xacro="http://www.ros.org/wiki/xacro">

    <xacro:property name="threshold" value="0.01"/>
    <xacro:property name="lower_limit" value="-0.436323"/>
    <xacro:property name="upper_limit" value="0.7853982"/>

    <link name="yaw">
        <inertial>
            <mass value="0.592087"/>
            <origin xyz="0 0 0.0127"/>
            <inertia ixx="6.17e-4" ixy="0." ixz="0." iyy="6.182e-4"
                     iyz="0." izz="1.07e-3"/>
        </inertial>
        <visual>
            <origin xyz="0 0 0" rpy="0 0 0"/>
            <geometry>
                <mesh filename="package://rm_description/meshes/standard/yaw.stl" scale="0.001 0.001 0.001" />
            </geometry>
        </visual>
        <collision>
            <origin xyz="0 0 0" rpy="0 0 0"/>
            <geometry>
                <mesh filename="package://rm_description/meshes/standard/yaw.stl"  scale="0.001 0.001 0.001" />
            </geometry>
        </collision>
    </link>

    <joint name="yaw_joint" type="continuous">
        <origin xyz="0 0 0.0696"
                rpy="0 0 0"/>
        <dynamics damping="0.0" friction="0.1"/>
        <parent link="base_link"/>
        <child link="yaw"/>
        <axis xyz="0 0 1"/>
    </joint>

    <link name="pitch">
        <inertial>
            <mass value="1.538674"/>
            <origin xyz="0.009047 -0.00307 0.019014"/>
            <inertia ixx="1.148e-2" ixy="1.569e-3" ixz="2.374e-3" iyy="2.472e-2"
                     iyz="-8.276e-4" izz="2.189e-2"/>
        </inertial>
        <visual>
            <origin xyz="0 0 0" rpy="0 0 0"/>
            <geometry>
                <mesh filename="package://rm_description/meshes/standard/pitch.stl" scale="0.001 0.001 0.001" />
            </geometry>
        </visual>
        <collision>
            <origin xyz="0 0 0" rpy="0 0 0"/>
            <geometry>
                <mesh filename="package://rm_description/meshes/standard/pitch.stl" scale="0.001 0.001 0.001"/>
            </geometry>
        </collision>
    </link>

    <joint name="pitch_joint" type="revolute">
        <origin xyz="0 0 0.189" rpy="0 0 0"/>
        <dynamics damping="0.0" friction="0.1"/>
        <limit effort="1.2" velocity="13.82" lower="${lower_limit}" upper="${upper_limit}"/>
        <!--        <safety_controller k_velocity="10"-->
        <!--                           k_position="15"-->
        <!--                           soft_lower_limit="${lower_limit+threshold}"-->
        <!--                           soft_upper_limit="${upper_limit-threshold}"/>-->
        <parent link="yaw"/>
        <child link="pitch"/>
        <axis xyz="0 1 0 "/>
    </joint>

</robot>